Workbook

Sheet Count Sheet 
D2: Count Sheet
B5: Quick Chick | G5: Line | K5: Waste
B7: Flavor | D7: SM | E7: LG | G7: Flavor | K7: Flavor
B8: Barbie Q | G8: Barbie Q | K8: BBQ
B9: Buffalo Barclay | G9: Buffalo Barclay | K9: BB
B10: Classic Carol | G10: Classic Carol | K10: CC
B11: Cranberry Kelli | G11: Cranberry Kelli | K11: CK
B12: Dixie Chick | G12: Dixie Chick | K12: DC
B13: Fancy Nancy | G13: Fancy Nancy | K13: FN
B14: Fruity Fran | G14: Fruity Fran | K14: FF
B15: Jalapeño Holly | G15: Jalapeño Holly | K15: JH
B16: Kickin Kay Lynne | G16: Kickin Kay Lynne | K16: KKL
B17: Lauryn's L. Basil | G17: Lauryn's L. Basil | K17: LLB
B18: Local Flavor | G18: Local Flavor | K18: LOCAL
B19: Olivia's Old South | G19: Olivia's Old South | K19: OOS
... B29: Count all chicken salad Quick Chicks by container. Count Side Items by the 1/2 pan. | G29: Count mixed flavors in the line coolers, reach-ins, and walk-in by the pound. Count side items by the 1/2 pan. | K29: Count all waste in pounds.
C31: Todays Date: | H31: Color to Discard:

Sheet Production Guide
A1: Next Day's Sales Forecast | K1: Day After Tomorrow's Sales Forecast
E2: 4500 | R2: 4500
A4: Small Quick Chick | G4: Large Quick Chick | N4: Line- (Any mixed flavors not in Quick Chick) | U4: Totals
A5: Flavor | C5: Par | D5: On Hand | E5: QC's to Prep | G5: Flavor | I5: Par | J5: On Hand | K5: QC's to Prep | N5: Flavor | P5: Par | Q5: On Hand | R5: #s to Prep | U5: Flavor | W5: Par | X5: On Hand | Y5: #s to Prep
A6: Barbie Q | C6: =ROUNDUP(((($E$2*1.35)/100)*'All Data'!I11),0) -> 2 | D6: 0 | E6: =IF('All Data'!J11<0,0,'All Data'!J11) -> 2 | G6: Barbie Q | I6: =ROUNDUP(((($E$2*1.35)/100)*'All Data'!H30),0) -> 2 | J6: 0 | K6: =IF('All Data'!I30<0,0,'All Data'!I30) -> 2 | N6: Barbie Q | P6: =ROUNDUP(((($E$2*1.35)/100)*'All Data'!I51),0) -> 4 | Q6: 0 | R6: =IF('All Data'!J51<0,0,'All Data'!J51) -> 4 | U6: Barbie Q | W6: =(C6*0.5)+I6+P6 -> 7 | X6: =(D6*0.5)+J6+Q6 -> 0 | Y6: =ROUNDUP(IF((W6-X6)<0,0,(W6-X6))+C25,0) -> 7
A7: Buffalo Barclay | C7: =ROUNDUP(((($E$2*1.35)/100)*'All Data'!I12),0) -> 3 | D7: 0 | E7: =IF('All Data'!J12<0,0,'All Data'!J12) -> 3 | G7: Buffalo Barclay | I7: =ROUNDUP(((($E$2*1.35)/100)*'All Data'!H31),0) -> 3 | J7: 0 | K7: =IF('All Data'!I31<0,0,'All Data'!I31) -> 3 | N7: Buffalo Barclay | P7: =ROUNDUP(((($E$2*1.35)/100)*'All Data'!I52),0)+K48 -> 9 | Q7: 0 | R7: =IF('All Data'!J52<0,0,'All Data'!J52) -> 9 | U7: Buffalo Barclay | W7: =(C7*0.5)+I7+P7 -> 13.5 | X7: =(D7*0.5)+J7+Q7 -> 0 | Y7: =ROUNDUP(IF((W7-X7)<0,0,(W7-X7))+C26,0) -> 14
A8: Classic Carol | C8: =ROUNDUP(((($E$2*1.35)/100)*'All Data'!I13),0) -> 9 | D8: 0 | E8: =IF('All Data'!J13<0,0,'All Data'!J13) -> 9 | G8: Classic Carol | I8: =ROUNDUP(((($E$2*1.35)/100)*'All Data'!H32),0) -> 13 | J8: 0 | K8: =IF('All Data'!I32<0,0,'All Data'!I32) -> 13 | N8: Classic Carol | P8: =ROUNDUP(((($E$2*1.35)/100)*'All Data'!I53),0) -> 20 | Q8: 0 | R8: =IF('All Data'!J53<0,0,'All Data'!J53) -> 20 | U8: Classic Carol | W8: =(C8*0.5)+I8+P8 -> 37.5 | X8: =(D8*0.5)+J8+Q8 -> 0 | Y8: =ROUNDUP(IF((W8-X8)<0,0,(W8-X8))+C27,0) -> 38
A9: Cranberry Kelli | C9: =ROUNDUP(((($E$2*1.35)/100)*'All Data'!I14),0) -> 5 | D9: 0 | E9: =IF('All Data'!J14<0,0,'All Data'!J14) -> 5 | G9: Cranberry Kelli | I9: =ROUNDUP(((($E$2*1.35)/100)*'All Data'!H33),0) -> 6 | J9: 0 | K9: =IF('All Data'!I33<0,0,'All Data'!I33) -> 6 | N9: Cranberry Kelli | P9: =ROUNDUP(((($E$2*1.35)/100)*'All Data'!I54),0) -> 8 | Q9: 0 | R9: =IF('All Data'!J54<0,0,'All Data'!J54) -> 8 | U9: Cranberry Kelli | W9: =(C9*0.5)+I9+P9 -> 16.5 | X9: =(D9*0.5)+J9+Q9 -> 0 | Y9: =ROUNDUP(IF((W9-X9)<0,0,(W9-X9))+C28,0) -> 17
A10: Dixie Chick | C10: =ROUNDUP(((($E$2*1.35)/100)*'All Data'!I15),0) -> 2 | D10: 0 | E10: =IF('All Data'!J15<0,0,'All Data'!J15) -> 2 | G10: Dixie Chick | I10: =ROUNDUP(((($E$2*1.35)/100)*'All Data'!H34),0) -> 3 | J10: 0 | K10: =IF('All Data'!I34<0,0,'All Data'!I34) -> 3 | N10: Dixie Chick | P10: =ROUNDUP(((($E$2*1.35)/100)*'All Data'!I55),0) -> 5 | Q10: 0 | R10: =IF('All Data'!J55<0,0,'All Data'!J55) -> 5 | U10: Dixie Chick | W10: =(C10*0.5)+I10+P10 -> 9 | X10: =(D10*0.5)+J10+Q10 -> 0 | Y10: =ROUNDUP(IF((W10-X10)<0,0,(W10-X10))+C29,0) -> 9
A11: Fancy Nancy | C11: =ROUNDUP(((($E$2*1.35)/100)*'All Data'!I16),0) -> 9 | D11: 0 | E11: =IF('All Data'!J16<0,0,'All Data'!J16) -> 9 | G11: Fancy Nancy | I11: =ROUNDUP(((($E$2*1.35)/100)*'All Data'!H35),0) -> 13 | J11: 0 | K11: =IF('All Data'!I35<0,0,'All Data'!I35) -> 13 | N11: Fancy Nancy | P11: =ROUNDUP(((($E$2*1.35)/100)*'All Data'!I56),0) -> 22 | Q11: 0 | R11: =IF('All Data'!J56<0,0,'All Data'!J56) -> 22 | U11: Fancy Nancy | W11: =(C11*0.5)+I11+P11 -> 39.5 | X11: =(D11*0.5)+J11+Q11 -> 0 | Y11: =ROUNDUP(IF((W11-X11)<0,0,(W11-X11))+C30,0) -> 40
A12: Fruity Fran | C12: =ROUNDUP(((($E$2*1.35)/100)*'All Data'!I17),0) -> 4 | D12: 0 | E12: =IF('All Data'!J17<0,0,'All Data'!J17) -> 4 | G12: Fruity Fran | I12: =ROUNDUP(((($E$2*1.35)/100)*'All Data'!H36),0) -> 4 | J12: 0 | K12: =IF('All Data'!I36<0,0,'All Data'!I36) -> 4 | N12: Fruity Fran | P12: =ROUNDUP(((($E$2*1.35)/100)*'All Data'!I57),0) -> 9 | Q12: 0 | R12: =IF('All Data'!J57<0,0,'All Data'!J57) -> 9 | U12: Fruity Fran | W12: =(C12*0.5)+I12+P12 -> 15 | X12: =(D12*0.5)+J12+Q12 -> 0 | Y12: =ROUNDUP(IF((W12-X12)<0,0,(W12-X12))+C31,0) -> 15
A13: Jalapeño Holly | C13: =ROUNDUP(((($E$2*1.35)/100)*'All Data'!I18),0) -> 3 | D13: 0 | E13: =IF('All Data'!J18<0,0,'All Data'!J18) -> 3 | G13: Jalapeño Holly | I13: =ROUNDUP(((($E$2*1.35)/100)*'All Data'!H37),0) -> 4 | J13: 0 | K13: =IF('All Data'!I37<0,0,'All Data'!I37) -> 4 | N13: Jalapeño Holly | P13: =ROUNDUP(((($E$2*1.35)/100)*'All Data'!I58),0)+K48 -> 9 | Q13: 0 | R13: =IF('All Data'!J58<0,0,'All Data'!J58) -> 9 | U13: Jalapeño Holly | W13: =(C13*0.5)+I13+P13 -> 14.5 | X13: =(D13*0.5)+J13+Q13 -> 0 | Y13: =ROUNDUP(IF((W13-X13)<0,0,(W13-X13))+C32,0) -> 15
A14: Kickin Kay Lynne | C14: =ROUNDUP(((($E$2*1.35)/100)*'All Data'!I19),0) -> 3 | D14: 0 | E14: =IF('All Data'!J19<0,0,'All Data'!J19) -> 3 | G14: Kickin Kay Lynne | I14: =ROUNDUP(((($E$2*1.35)/100)*'All Data'!H38),0) -> 2 | J14: 0 | K14: =IF('All Data'!I38<0,0,'All Data'!I38) -> 2 | N14: Kickin Kay Lynne | P14: =ROUNDUP(((($E$2*1.35)/100)*'All Data'!I59),0) -> 6 | Q14: 0 | R14: =IF('All Data'!J59<0,0,'All Data'!J59) -> 6 | U14: Kickin Kay Lynne | W14: =(C14*0.5)+I14+P14 -> 9.5 | X14: =(D14*0.5)+J14+Q14 -> 0 | Y14: =ROUNDUP(IF((W14-X14)<0,0,(W14-X14))+C33,0) -> 10
A15: Lauryn's L. Basil | C15: =ROUNDUP(((($E$2*1.35)/100)*'All Data'!I20),0) -> 3 | D15: 0 | E15: =IF('All Data'!J20<0,0,'All Data'!J20) -> 3 | G15: Lauryn's L. Basil | I15: =ROUNDUP(((($E$2*1.35)/100)*'All Data'!H39),0) -> 3 | J15: 0 | K15: =IF('All Data'!I39<0,0,'All Data'!I39) -> 3 | N15: Lauryn's L. Basil | P15: =ROUNDUP(((($E$2*1.35)/100)*'All Data'!I60),0) -> 5 | Q15: 0 | R15: =IF('All Data'!J60<0,0,'All Data'!J60) -> 5 | U15: Lauryn's L. Basil | W15: =(C15*0.5)+I15+P15 -> 9.5 | X15: =(D15*0.5)+J15+Q15 -> 0 | Y15: =ROUNDUP(IF((W15-X15)<0,0,(W15-X15))+C34,0) -> 10
A16: Local Flavor | C16: =ROUNDUP(((($E$2*1.35)/100)*'All Data'!I21),0) -> 0 | D16: 0 | E16: =IF('All Data'!J21<0,0,'All Data'!J21) -> 0 | G16: Local Flavor | I16: =ROUNDUP(((($E$2*1.35)/100)*'All Data'!H40),0) -> 0 | J16: 0 | K16: =IF('All Data'!I40<0,0,'All Data'!I40) -> 0 | N16: Local Flavor | P16: =ROUNDUP(((($E$2*1.35)/100)*'All Data'!I61),0) -> 0 | Q16: 0 | R16: =IF('All Data'!J61<0,0,'All Data'!J61) -> 0 | U16: Local Flavor | W16: =(C16*0.5)+I16+P16 -> 0 | X16: =(D16*0.5)+J16+Q16 -> 0 | Y16: =ROUNDUP(IF((W16-X16)<0,0,(W16-X16))+C35,0) -> 0
A17: Olivia's Old South | C17: =ROUNDUP(((($E$2*1.35)/100)*'All Data'!I22),0) -> 4 | D17: 0 | E17: =IF('All Data'!J22<0,0,'All Data'!J22) -> 4 | G17: Olivia's Old South | I17: =ROUNDUP(((($E$2*1.35)/100)*'All Data'!H41),0) -> 4 | J17: 0 | K17: =IF('All Data'!I41<0,0,'All Data'!I41) -> 4 | N17: Olivia's Old South | P17: =ROUNDUP(((($E$2*1.35)/100)*'All Data'!I62),0) -> 9 | Q17: 0 | R17: =IF('All Data'!J62<0,0,'All Data'!J62) -> 9 | U17: Olivia's Old South | W17: =(C17*0.5)+I17+P17 -> 15 | X17: =(D17*0.5)+J17+Q17 -> 0 | Y17: =ROUNDUP(IF((W17-X17)<0,0,(W17-X17))+C36,0) -> 15
A18: Sassy Scotty | C18: =ROUNDUP(((($E$2*1.35)/100)*'All Data'!I23),0) -> 5 | D18: 0 | E18: =IF('All Data'!J23<0,0,'All Data'!J23) -> 5 | G18: Sassy Scotty | I18: =ROUNDUP(((($E$2*1.35)/100)*'All Data'!H42),0) -> 5 | J18: 0 | K18: =IF('All Data'!I42<0,0,'All Data'!I42) -> 5 | N18: Sassy Scotty | P18: =ROUNDUP(((($E$2*1.35)/100)*'All Data'!I63),0)+K48 -> 13 | Q18: 0 | R18: =IF('All Data'!J63<0,0,'All Data'!J63) -> 13 | U18: Sassy Scotty | W18: =(C18*0.5)+I18+P18 -> 20.5 | X18: =(D18*0.5)+J18+Q18 -> 0 | Y18: =ROUNDUP(IF((W18-X18)<0,0,(W18-X18))+C37,0) -> 21
A19: LTO | C19: =ROUNDUP(((($E$2*1.35)/100)*'All Data'!I24),0) -> 3 | D19: 0 | E19: =IF('All Data'!J24<0,0,'All Data'!J24) -> 3 | G19: LTO | I19: =ROUNDUP(((($E$2*1.35)/100)*'All Data'!H43),0) -> 2 | J19: 0 | K19: =IF('All Data'!I43<0,0,'All Data'!I43) -> 2 | N19: LTO | P19: =ROUNDUP(((($E$2*1.35)/100)*'All Data'!I64),0) -> 4 | Q19: 0 | R19: =IF('All Data'!J64<0,0,'All Data'!J64) -> 4 | U19: LTO | W19: =(C19*0.5)+I19+P19 -> 7.5 | X19: =(D19*0.5)+J19+Q19 -> 0 | Y19: =ROUNDUP(IF((W19-X19)<0,0,(W19-X19))+C38,0) -> 8
A20: Egg Salad | C20: =ROUNDUP(((($E$2*1.35)/100)*'All Data'!I25),0) -> 3 | D20: 0 | E20: =IF('All Data'!J25<0,0,'All Data'!J25) -> 3 | G20: Egg Salad | I20: =ROUNDUP(((($E$2*1.35)/100)*'All Data'!H44),0) -> 2 | J20: 0 | K20: =IF('All Data'!I44<0,0,'All Data'!I44) -> 2 | N20: Egg Salad | P20: =ROUNDUP(((($E$2*1.35)/100)*'All Data'!I65),0) -> 4 | Q20: 0 | R20: =IF('All Data'!J65<0,0,'All Data'!J65) -> 4 | U20: Egg Salad | W20: =(C20*0.5)+I20+P20 -> 7.5 | X20: =(D20*0.5)+J20+Q20 -> 0 | Y20: =ROUNDUP(IF((W20-X20)<0,0,(W20-X20))+C39,0) -> 8
A21: Pimento Cheese | C21: =ROUNDUP(((($E$2*1.35)/100)*'All Data'!I26),0) -> 4 | D21: 0 | E21: =IF('All Data'!J26<0,0,'All Data'!J26) -> 4 | G21: Pimento Cheese | I21: =ROUNDUP(((($E$2*1.35)/100)*'All Data'!H45),0) -> 3 | J21: 0 | K21: =IF('All Data'!I45<0,0,'All Data'!I45) -> 3 | N21: Pimento Cheese | P21: =ROUNDUP(((($E$2*1.35)/100)*'All Data'!I66),0) -> 3 | Q21: 0 | R21: =IF('All Data'!J66<0,0,'All Data'!J66) -> 3 | U21: Pimento Cheese | W21: =(C21*0.5)+I21+P21 -> 8 | X21: =(D21*0.5)+J21+Q21 -> 0 | Y21: =ROUNDUP(IF((W21-X21)<0,0,(W21-X21))+C40,0) -> 8
A22: Spicy P. Cheese | C22: =ROUNDUP(((($E$2*1.35)/100)*'All Data'!I27),0) -> 2 | D22: 0 | E22: =IF('All Data'!J27<0,0,'All Data'!J27) -> 2 | G22: Spicy P. Cheese | I22: =ROUNDUP(((($E$2*1.35)/100)*'All Data'!H46),0) -> 1 | J22: 0 | K22: =IF('All Data'!I46<0,0,'All Data'!I46) -> 1 | N22: Spicy P. Cheese | P22: =ROUNDUP(((($E$2*1.35)/100)*'All Data'!I67),0) -> 2 | Q22: 0 | R22: =IF('All Data'!J67<0,0,'All Data'!J67) -> 2 | U22: Spicy P. Cheese | W22: =(C22*0.5)+I22+P22 -> 4 | X22: =(D22*0.5)+J22+Q22 -> 0 | Y22: =ROUNDUP(IF((W22-X22)<0,0,(W22-X22))+C41,0) -> 4
A24: Tomorrow's Catering #'s
A25: Barbie Q | G25: Side Item | I25: Par | J25: On Hand | K25: 1/2 Pan Prep
A26: Buffalo Barclay | G26: Broccoli Salad | I26: =(((($E$2*1.35)/100)*'All Data'!J72)/'All Data'!K72) -> 4.3061876 | K26: =IF(((I26-J26+C42)<0),0,(I26-J26+(C42/5.63))) -> 4.3061876 | N26: Broccoli salad yields (2) 1/2 pans. Pasta Salad yields (3) 1/2 pans.
A27: Classic Carol | G27: Fresh Fruit | I27: =(((($E$2*1.35)/100)*'All Data'!J73)/'All Data'!K73) -> 1.7330889 | K27: =IF(((I27-J27+C43)<0),0,(I27-J27+(C43/8.785))) -> 1.7330889
A28: Cranberry Kelli | G28: Grape Salad | I28: =(((($E$2*1.35)/100)*'All Data'!J74)/'All Data'!K74) -> 4.2050022 | K28: =IF(((I28-J28+C44)<0),0,(I28-J28+(C44/8.25))) -> 4.2050022
A29: Dixie Chick | G29: Pasta Salad | I29: =(((($E$2*1.35)/100)*'All Data'!J75)/'All Data'!K75) -> 2.7275683 | K29: =IF(((I29-J29+C45)<0),0,(I29-J29+(C45/6.79))) -> 2.7275683
A30: Fancy Nancy
A31: Fruity Fran
A32: Jalapeño Holly | G32: Produce Item | I32: Par
A33: Kickin Kay Lynne | G33: Broccoli Lexans | I33: =Future!I26/2 -> 2.1530938
A34: Lauryn's L. Basil | G34: Dried Grape Lexans | I34: =Future!I28/2 -> 2.1025011
A35: Local Flavor
A36: Olivia's Old South | G36: Salads | I36: Par
A37: Sassy Scotty | G37: Classic Salads | I37: ='All Data'!G85 -> 9
A38: LTO | G38: Seasonal Salads | I38: ='All Data'!G86 -> 9
A39: Egg Salad
A40: Pimento Cheese
A41: Spicy P. Cheese
A42: Broccoli Salad
...

Sheet 2 Prep Cooks
B1: Date:
B3: Today's Forecast: | E3: ='Production Guide'!E2 -> 4500
A6: Daily Production List | G6: Item | H6: Prep
G7: Broccoli Lexis | H7: =Future!AE5 -> 2.1530938
G8: Wet Grape Lexis | H8: =Future!AE6 -> 1.7330889
A9: SM | B9: LG | C9: Cook | D9: Flavor | E9: #'s to Prep | G9: Dry Grape Lexis | H9: =Future!AE7 -> 2.4028584
A10: ='Production Guide'!E8 -> 9 | B10: ='Production Guide'!K8 -> 13 | C10: C1 | D10: Classic Carol | E10: ='Production Guide'!Y8 -> 38 | G10: Pasta Salad Batches | H10: =Future!AE8 -> 1.0910273
A11: ='Production Guide'!E9 -> 5 | B11: ='Production Guide'!K9 -> 6 | C11: C1 | D11: Cranberry Kelli | E11: ='Production Guide'!Y9 -> 17 | G11: Grape Salad Dressing | H11: =Future!AF9 -> 2
A12: ='Production Guide'!E17 -> 4 | B12: ='Production Guide'!K17 -> 4 | C12: C1 | D12: Olivia's Old South | E12: ='Production Guide'!Y17 -> 15
A13: ='Production Guide'!E12 -> 4 | B13: ='Production Guide'!K12 -> 4 | C13: C1 | D13: Fruity Fran | E13: ='Production Guide'!Y12 -> 15 | G13: Salads | H13: Par
A14: ='Production Guide'!E19 -> 3 | B14: ='Production Guide'!K19 -> 2 | C14: C1 | D14: LTO | E14: ='Production Guide'!Y19 -> 8 | G14: Classic Salads | H14: ='All Data'!G85 -> 9
A15: ='Production Guide'!E10 -> 2 | B15: ='Production Guide'!K10 -> 3 | C15: C1 | D15: Dixie Chick | E15: ='Production Guide'!Y10 -> 9 | G15: Seasonal Salads | H15: ='All Data'!G86 -> 9
A16: ='Production Guide'!E16 -> 0 | B16: ='Production Guide'!K16 -> 0 | C16: C1 | D16: Local Flavor | E16: ='Production Guide'!Y16 -> 0
A17: ='Production Guide'!E15 -> 3 | B17: ='Production Guide'!K15 -> 3 | C17: C1 | D17: Lauryn's Lemon Basil | E17: ='Production Guide'!Y15 -> 10 | F17: KKL
A18: ='Production Guide'!E18 -> 5 | B18: ='Production Guide'!K18 -> 5 | C18: C2 | D18: Sassy Scotty | E18: ='Production Guide'!Y18 -> 21 | F18: =E22/3 -> 3
A19: ='Production Guide'!E11 -> 9 | B19: ='Production Guide'!K11 -> 13 | C19: C2 | D19: Fancy Nancy | E19: ='Production Guide'!Y11 -> 40
A20: ='Production Guide'!E7 -> 3 | B20: ='Production Guide'!K7 -> 3 | C20: C2 | D20: Buffalo Barclay | E20: ='Production Guide'!Y7 -> 14 | F20: =E22/3 -> 3
A21: ='Production Guide'!E13 -> 3 | B21: ='Production Guide'!K13 -> 4 | C21: C2 | D21: Jalapeño Holly | E21: ='Production Guide'!Y13 -> 15 | F21: =E22/3 -> 3
A22: ='Production Guide'!E14 -> 3 | B22: ='Production Guide'!K14 -> 2 | C22: C2 | D22: Kickin Kay Lynne | E22: =MROUND('Production Guide'!Y14,3) -> 9
A23: ='Production Guide'!E6 -> 2 | B23: ='Production Guide'!K6 -> 2 | C23: C2 | D23: Barbie Q | E23: ='Production Guide'!Y6 -> 7
A24: ='Production Guide'!E21 -> 4 | B24: ='Production Guide'!K21 -> 3 | C24: C2 | D24: Pimento Cheese | E24: ='Production Guide'!Y21 -> 8
A25: ='Production Guide'!E22 -> 2 | B25: ='Production Guide'!K22 -> 1 | C25: C2 | D25: Spicy Pimento Cheese | E25: ='Production Guide'!Y22 -> 4
A26: ='Production Guide'!E20 -> 3 | B26: ='Production Guide'!K20 -> 2 | C26: C2 | D26: Egg Salad | E26: ='Production Guide'!Y20 -> 8
D27: Total Mixed Flavors | E27: =SUM(E10:E23)-E22 -> 209
C29: Cook | D29: Ingredient | E29: Cups to Prep | G29: Salad Item Prep
C30: C2 | D30: Apples | E30: =(E19+E13)*0.25 -> 13.75 | G30: Salad Mix
C31: C2 | D31: Eggs | E31: =E12*0.25 -> 3.75 | G31: Strawberries
C32: C2 | D32: Onions | E32: =E15*0.25 -> 2.25 | G32: Unpeeled Apples
C33: C2 | D33: Bacon | E33: =(E18*0.25)+(E16*0.25) -> 5.25 | G33: Cucumbers
C34: C2 | D34: Pineapple | E34: =E13*0.25 -> 3.75
D35: Side | E35: 1/2 Pans | G35: Classic Carol for Tomorrow
D36: Broccoli Salad | E36: ='Production Guide'!K26 -> 4.3061876 | G36: =Future!W24 -> 205
D37: Fresh Fruit | E37: ='Production Guide'!K27 -> 1.7330889 | G37: C1- seasonal salad ingred, strawberries for fresh fruit & pasta salad
D38: Grape Salad | E38: ='Production Guide'!K28 -> 4.2050022
D39: Pasta Salad | E39: ='Production Guide'!K29 -> 2.7275683
C40: Broccoli salad yields (2) 1/2 pans. Pasta Salad yields (3) 1/2 pans. | G40: C2 & C3- sinks, sanitizer bucket, sanitize work stations, bowls & lids
A42: Sandwich line will quick chick the flavors highlighted. | G42: C4- Temperature logs

Sheet 3 Prep Cooks
B1: Date:
B3: Today's Forecast: | E3: ='Production Guide'!E2 -> 4500
A6: Daily Production List | G6: Item | H6: Prep
G7: Broccoli Lexis | H7: =Future!AE5 -> 2.1530938
G8: Wet Grape Lexis | H8: =Future!AE6 -> 1.7330889
A9: SM | B9: QC | C9: Cook | D9: Flavor | E9: #'s to Prep | G9: Dry Grape Lexis | H9: =Future!AE7 -> 2.4028584
A10: ='Production Guide'!E8 -> 9 | B10: ='Production Guide'!K8 -> 13 | C10: C1 | D10: Classic Carol | E10: ='Production Guide'!Y8 -> 38 | G10: Pasta Salad Batches | H10: =Future!AE8 -> 1.0910273
A11: ='Production Guide'!E17 -> 4 | B11: ='Production Guide'!K17 -> 4 | C11: C1 | D11: Olivia's Old South | E11: ='Production Guide'!Y17 -> 15 | G11: Grape Salad Dressing | H11: =Future!AF9 -> 2
A12: ='Production Guide'!E12 -> 4 | B12: ='Production Guide'!K12 -> 4 | C12: C1 | D12: Fruity Fran | E12: ='Production Guide'!Y12 -> 15
A13: ='Production Guide'!E19 -> 3 | B13: ='Production Guide'!K19 -> 2 | C13: C1 | D13: LTO | E13: ='Production Guide'!Y19 -> 8 | G13: Salads | H13: Par
A14: ='Production Guide'!E6 -> 2 | B14: ='Production Guide'!K6 -> 2 | C14: C1 | D14: Barbie Q | E14: ='Production Guide'!Y6 -> 7 | G14: Classic Salads | H14: ='All Data'!G85 -> 9
A15: ='Production Guide'!E10 -> 2 | B15: ='Production Guide'!K10 -> 3 | C15: C1 | D15: Dixie Chick | E15: ='Production Guide'!Y10 -> 9 | G15: Seasonal Salads | H15: ='All Data'!G86 -> 9
A16: ='Production Guide'!E9 -> 5 | B16: ='Production Guide'!K9 -> 6 | C16: C2 | D16: Cranberry Kelli | E16: ='Production Guide'!Y9 -> 17
A17: ='Production Guide'!E11 -> 9 | B17: ='Production Guide'!K11 -> 13 | C17: C2 | D17: Fancy Nancy | E17: ='Production Guide'!Y11 -> 40
A18: ='Production Guide'!E16 -> 0 | B18: ='Production Guide'!K16 -> 0 | C18: C2 | D18: Local Flavor | E18: ='Production Guide'!Y16 -> 0
A19: ='Production Guide'!E15 -> 3 | B19: ='Production Guide'!K15 -> 3 | C19: C2 | D19: Lauryn's Lemon Basil | E19: ='Production Guide'!Y15 -> 10
A20: ='Production Guide'!E21 -> 4 | B20: ='Production Guide'!K21 -> 3 | C20: C2 | D20: Pimento Cheese | E20: ='Production Guide'!Y21 -> 8
A21: ='Production Guide'!E22 -> 2 | B21: ='Production Guide'!K22 -> 1 | C21: C2 | D21: Spicy Pimento Cheese | E21: ='Production Guide'!Y22 -> 4 | F21: KKL
A22: ='Production Guide'!E18 -> 5 | B22: ='Production Guide'!K18 -> 5 | C22: C3 | D22: Sassy Scotty | E22: ='Production Guide'!Y18 -> 21 | F22: =E25/3 -> 3
A23: ='Production Guide'!E13 -> 3 | B23: ='Production Guide'!K13 -> 4 | C23: C3 | D23: Jalapeño Holly | E23: ='Production Guide'!Y13 -> 15 | F23: =E25/3 -> 3
A24: ='Production Guide'!E7 -> 3 | B24: ='Production Guide'!K7 -> 3 | C24: C3 | D24: Buffalo Barclay | E24: ='Production Guide'!Y7 -> 14 | F24: =E25/3 -> 3
A25: ='Production Guide'!E14 -> 3 | B25: ='Production Guide'!K14 -> 2 | C25: C3 | D25: Kickin Kay Lynne | E25: =MROUND('Production Guide'!Y14,3) -> 9
A26: ='Production Guide'!E20 -> 3 | B26: ='Production Guide'!K20 -> 2 | C26: C3 | D26: Egg Salad | E26: ='Production Guide'!Y20 -> 8
D27: Total Mixed Flavors | E27: =SUM(E10:E25)-E20-E21-E25 -> 209
G28: Salad Item Prep
C29: Cook | D29: Ingredient | E29: Cups to Prep | G29: Salad Mix
C30: C1 | D30: Apples | E30: =(E17+E12)*0.25 -> 13.75 | G30: Strawberries
C31: C1 | D31: Eggs | E31: =E11*0.25 -> 3.75 | G31: Unpeeled Apples
C32: C1 | D32: Onions | E32: =E15*0.25 -> 2.25 | G32: Cucumbers
C33: C1 | D33: Bacon | E33: =(E22*0.25)+(E18*0.25) -> 5.25
C34: C1 | D34: Pineapple | E34: =E12*0.25 -> 3.75 | G34: Classic Carol for Tomorrow
D35: Side | E35: 1/2 Pans | G35: =Future!W24 -> 205
D36: Broccoli Salad | E36: ='Production Guide'!K26 -> 4.3061876
D37: Fresh Fruit | E37: ='Production Guide'!K27 -> 1.7330889 | G37: C1- seasonal salad ingred, strawberries for fresh fruit & pasta salad
D38: Grape Salad | E38: ='Production Guide'!K28 -> 4.2050022
D39: Pasta Salad | E39: ='Production Guide'!K29 -> 2.7275683
G40: C2 & C3- sinks, sanitizer bucket, sanitize work stations, bowls & lids
C41: Broccoli salad yields (2) 1/2 pans. Pasta Salad yields (3) 1/2 pans.
G42: C4- Temperature logs
A43: Sandwich line will quick chick the flavors highlighted.

Sheet 4 Prep Cooks
B1: Date:
B3: Today's Forecast: | E3: ='Production Guide'!E2 -> 4500
A6: Daily Production List | G6: Item | H6: Prep
G7: Broccoli Lexis | H7: =Future!AE5 -> 2.1530938
G8: Wet Grape Lexis | H8: =Future!AE6 -> 1.7330889
A9: SM | B9: LG | C9: Cook | D9: Flavor | E9: #'s to Prep | G9: Dry Grape Lexis | H9: =Future!AE7 -> 2.4028584
A10: ='Production Guide'!E8 -> 9 | B10: ='Production Guide'!K8 -> 13 | C10: C2 | D10: Classic Carol | E10: ='Production Guide'!Y8 -> 38 | G10: Pasta Salad Batches | H10: =Future!AE8 -> 1.0910273
A11: ='Production Guide'!E17 -> 4 | B11: ='Production Guide'!K17 -> 4 | C11: C2 | D11: Olivia's Old South | E11: ='Production Guide'!Y17 -> 15 | G11: Grape Salad Dressing | H11: =Future!AF9 -> 2
A12: ='Production Guide'!E12 -> 4 | B12: ='Production Guide'!K12 -> 4 | C12: C2 | D12: Fruity Fran | E12: ='Production Guide'!Y12 -> 15
A13: ='Production Guide'!E19 -> 3 | B13: ='Production Guide'!K19 -> 2 | C13: C2 | D13: LTO | E13: ='Production Guide'!Y19 -> 8 | G13: Salads | H13: Par
A14: ='Production Guide'!E10 -> 2 | B14: ='Production Guide'!K10 -> 3 | C14: C2 | D14: Dixie Chick | E14: ='Production Guide'!Y10 -> 9 | G14: Classic Salads | H14: ='All Data'!G85 -> 9
A15: ='Production Guide'!E9 -> 5 | B15: ='Production Guide'!K9 -> 6 | C15: C3 | D15: Cranberry Kelli | E15: ='Production Guide'!Y9 -> 17 | G15: Seasonal Salads | H15: ='All Data'!G86 -> 9
A16: ='Production Guide'!E11 -> 9 | B16: ='Production Guide'!K11 -> 13 | C16: C3 | D16: Fancy Nancy | E16: ='Production Guide'!Y11 -> 40
A17: ='Production Guide'!E16 -> 0 | B17: ='Production Guide'!K16 -> 0 | C17: C3 | D17: Local Flavor | E17: ='Production Guide'!Y16 -> 0
A18: ='Production Guide'!E15 -> 3 | B18: ='Production Guide'!K15 -> 3 | C18: C3 | D18: Lauryn's Lemon Basil | E18: ='Production Guide'!Y15 -> 10
A19: ='Production Guide'!E21 -> 4 | B19: ='Production Guide'!K21 -> 3 | C19: C3 | D19: Pimento Cheese | E19: ='Production Guide'!Y21 -> 8
A20: ='Production Guide'!E22 -> 2 | B20: ='Production Guide'!K22 -> 1 | C20: C3 | D20: Spicy Pimento Cheese | E20: ='Production Guide'!Y22 -> 4 | F20: KKL
A21: ='Production Guide'!E18 -> 5 | B21: ='Production Guide'!K18 -> 5 | C21: C4 | D21: Sassy Scotty | E21: ='Production Guide'!Y18 -> 21 | F21: =E24/3 -> 3
A22: ='Production Guide'!E13 -> 3 | B22: ='Production Guide'!K13 -> 4 | C22: C4 | D22: Jalapeño Holly | E22: ='Production Guide'!Y13 -> 15 | F22: =E24/3 -> 3
A23: ='Production Guide'!E7 -> 3 | B23: ='Production Guide'!K7 -> 3 | C23: C4 | D23: Buffalo Barclay | E23: ='Production Guide'!Y7 -> 14 | F23: =E24/3 -> 3
A24: ='Production Guide'!E14 -> 3 | B24: ='Production Guide'!K14 -> 2 | C24: C4 | D24: Kickin Kay Lynne | E24: =MROUND('Production Guide'!Y14,3) -> 9
A25: ='Production Guide'!E6 -> 2 | B25: ='Production Guide'!K6 -> 2 | C25: C4 | D25: Barbie Q | E25: ='Production Guide'!Y6 -> 7
A26: ='Production Guide'!E20 -> 3 | B26: ='Production Guide'!K20 -> 2 | C26: C4 | D26: Egg Salad | E26: ='Production Guide'!Y20 -> 8
D27: Total Mixed Flavors | E27: =SUM(E10:E25)-E19-E20-E24 -> 209 | G27: Salad Item Prep
G28: Salad Mix
C29: Cook | D29: Ingredient | E29: Cups to Prep | G29: Strawberries
C30: C1 | D30: Apples | E30: =(E16+E12)*0.25 -> 13.75 | G30: Unpeeled Apples
C31: C1 | D31: Eggs | E31: =E11*0.25 -> 3.75 | G31: Cucumbers
C32: C1 | D32: Onions | E32: =E14*0.25 -> 2.25
C33: C1 | D33: Bacon | E33: =(E21*0.25)+(E17*0.25) -> 5.25
C34: C1 | D34: Pineapple | E34: =E12*0.25 -> 3.75 | G34: Classic Carol for Tomorrow
D35: Side | E35: 1/2 Pans | G35: =Future!W24 -> 205
D36: Broccoli Salad | E36: ='Production Guide'!K26 -> 4.3061876 | G36: C1- seasonal salad ingred, strawberries for fresh fruit & pasta salad
D37: Fresh Fruit | E37: ='Production Guide'!K27 -> 1.7330889
D38: Grape Salad | E38: ='Production Guide'!K28 -> 4.2050022
D39: Pasta Salad | E39: ='Production Guide'!K29 -> 2.7275683 | G39: C2 & C3- sinks, sanitizer bucket, sanitize work stations, bowls & lids
C40: Broccoli salad yields (2) 1/2 pans. Pasta Salad yields (3) 1/2 pans.
G41: C4- Temperature logs
A42: Sandwich line will quick chick the flavors highlighted.

Sheet 5 Prep Cooks 
B1: Date:
B3: Today's Forecast: | E3: ='Production Guide'!E2 -> 4500
A6: Daily Production List | G6: Item | H6: Prep
G7: Broccoli Lexis | H7: =Future!AE5 -> 2.1530938
G8: Wet Grape Lexis | H8: =Future!AE6 -> 1.7330889
A9: SM | B9: LG | C9: Cook | D9: Flavor | E9: #'s to Prep | G9: Dry Grape Lexis | H9: =Future!AE7 -> 2.4028584
A10: ='Production Guide'!E8 -> 9 | B10: ='Production Guide'!K8 -> 13 | C10: C2 | D10: Classic Carol | E10: ='Production Guide'!Y8 -> 38 | G10: Pasta Salad Batches | H10: =Future!AE8 -> 1.0910273
A11: ='Production Guide'!E9 -> 5 | B11: ='Production Guide'!K9 -> 6 | C11: C2 | D11: Cranberry Kelli | E11: ='Production Guide'!Y9 -> 17 | G11: Grape Salad Dressing | H11: =Future!AF9 -> 2
A12: ='Production Guide'!E17 -> 4 | B12: ='Production Guide'!K17 -> 4 | C12: C2 | D12: Olivia's Old South | E12: ='Production Guide'!Y17 -> 15
A13: ='Production Guide'!E20 -> 3 | B13: ='Production Guide'!K20 -> 2 | C13: C2 | D13: Egg Salad | E13: ='Production Guide'!Y20 -> 8 | G13: Salads | H13: Par
A14: ='Production Guide'!E10 -> 2 | B14: ='Production Guide'!K10 -> 3 | C14: C3 | D14: Dixie Chick | E14: ='Production Guide'!Y10 -> 9 | G14: Classic Salads | H14: ='All Data'!G85 -> 9
A15: ='Production Guide'!E12 -> 4 | B15: ='Production Guide'!K12 -> 4 | C15: C3 | D15: Fruity Fran | E15: ='Production Guide'!Y12 -> 15 | G15: Seasonal Salads | H15: ='All Data'!G86 -> 9
A16: ='Production Guide'!E19 -> 3 | B16: ='Production Guide'!K19 -> 2 | C16: C3 | D16: LTO | E16: ='Production Guide'!Y19 -> 8
A17: ='Production Guide'!E21 -> 4 | B17: ='Production Guide'!K21 -> 3 | C17: C3 | D17: Pimento Cheese | E17: ='Production Guide'!Y21 -> 8
A18: ='Production Guide'!E22 -> 2 | B18: ='Production Guide'!K22 -> 1 | C18: C3 | D18: Spicy Pimento Cheese | E18: ='Production Guide'!Y22 -> 4
A19: ='Production Guide'!E16 -> 0 | B19: ='Production Guide'!K16 -> 0 | C19: C4 | D19: Local Flavor | E19: ='Production Guide'!Y16 -> 0
A20: ='Production Guide'!E15 -> 3 | B20: ='Production Guide'!K15 -> 3 | C20: C4 | D20: Lauryn's Lemon Basil | E20: ='Production Guide'!Y15 -> 10
A21: ='Production Guide'!E6 -> 2 | B21: ='Production Guide'!K6 -> 2 | C21: C4 | D21: Barbie Q | E21: ='Production Guide'!Y6 -> 7
A22: ='Production Guide'!E11 -> 9 | B22: ='Production Guide'!K11 -> 13 | C22: C4 | D22: Fancy Nancy | E22: ='Production Guide'!Y11 -> 40 | F22: KKL
A23: ='Production Guide'!E18 -> 5 | B23: ='Production Guide'!K18 -> 5 | C23: C5 | D23: Sassy Scotty | E23: ='Production Guide'!Y18 -> 21 | F23: =E26/3 -> 3
A24: ='Production Guide'!E13 -> 3 | B24: ='Production Guide'!K13 -> 4 | C24: C5 | D24: Jalapeño Holly | E24: ='Production Guide'!Y13 -> 15 | F24: =E26/3 -> 3
A25: ='Production Guide'!E7 -> 3 | B25: ='Production Guide'!K7 -> 3 | C25: C5 | D25: Buffalo Barclay | E25: ='Production Guide'!Y7 -> 14 | F25: =E26/3 -> 3
A26: ='Production Guide'!E14 -> 3 | B26: ='Production Guide'!K14 -> 2 | C26: C5 | D26: Kickin Kay Lynne | E26: =MROUND('Production Guide'!Y14,3) -> 9
D27: Total Mixed Flavors | E27: =SUM(E10:E26)-E13-E17-E18-E26 -> 209 | G27: Salad Item Prep
G28: Salad Mix
C29: Cook | D29: Ingredient | E29: Cups to Prep | G29: Strawberries
C30: C1 | D30: Apples | E30: =(E15+E22)*0.25 -> 13.75 | G30: Unpeeled Apples
C31: C1 | D31: Eggs | E31: =E12*0.25 -> 3.75 | G31: Cucumbers
C32: C1 | D32: Onions | E32: =E14*0.25 -> 2.25
C33: C1 | D33: Bacon | E33: =(E23*0.25)+(E19*0.25) -> 5.25
C34: C1 | D34: Pineapples | E34: =E15*0.25 -> 3.75 | G34: Classic Carol for Tomorrow
D35: Side | E35: 1/2 Pans | G35: =Future!W24 -> 205
D36: Broccoli Salad | E36: ='Production Guide'!K26 -> 4.3061876 | G36: C1- seasonal salad ingred, strawberries for fresh fruit & pasta salad
D37: Fresh Fruit | E37: ='Production Guide'!K27 -> 1.7330889
D38: Grape Salad | E38: ='Production Guide'!K28 -> 4.2050022
D39: Pasta Salad | E39: ='Production Guide'!K29 -> 2.7275683 | G39: C2 & C3- sinks, sanitizer bucket, sanitize work stations, bowls & lids
C41: Broccoli salad yields (2) 1/2 pans. Pasta Salad yields (3) 1/2 pans. | G41: C4- Temperature logs
A43: Sandwich line will quick chick the flavors highlighted.

Sheet All Data
C2: Sales | F2: Updated by: | G2: Amanda Galbraith
C3: 142579.54 | F3: Date: | G3: 4.29.25
F4: Data Range: | G4: 3.23.25-4.26.25
P7: Directions:
A8: Quick Chicks of Chicken Salad | P8: Fill in the peach colored fields.
P9: *Make sure you enter the item sales numbers for the same total sales number that you enter in the top box.
A10: Small Bowls | F10: Flavor | G10: #'s Sold | H10: Total #'s | I10: Usage/100 | J10: Prep Amt | P10: **Example- Don't enter item sales for one day, but put the total sales of the week.
A11: Barbie Q | C11: 31 | F11: BBQ | G11: =C11 -> 31 | H11: =G11/2 -> 15.5 | I11: =G11/($C$3/100) -> 0.02174225 | J11: ='Production Guide'!C6-'Production Guide'!D6 -> 2 | P11: ***See CSCU if you need more direction!
A12: Buffalo Barclay | C12: 52 | F12: BB | G12: =C12 -> 52 | H12: =G12/2 -> 26 | I12: =G12/($C$3/100) -> 0.036470871 | J12: ='Production Guide'!C7-'Production Guide'!D7 -> 3
A13: Classic Carol | C13: 195 | F13: CC | G13: =C13 -> 195 | H13: =G13/2 -> 97.5 | I13: =G13/($C$3/100) -> 0.13676577 | J13: ='Production Guide'!C8-'Production Guide'!D8 -> 9
A14: Cranberry Kelli | C14: 106 | F14: CK | G14: =C14 -> 106 | H14: =G14/2 -> 53 | I14: =G14/($C$3/100) -> 0.074344468 | J14: ='Production Guide'!C9-'Production Guide'!D9 -> 5
A15: Dixie Chick | C15: 41 | F15: DC | G15: =C15 -> 41 | H15: =G15/2 -> 20.5 | I15: =G15/($C$3/100) -> 0.028755879 | J15: ='Production Guide'!C10-'Production Guide'!D10 -> 2
A16: Fancy Nancy | C16: 189 | F16: FN | G16: =C16 -> 189 | H16: =G16/2 -> 94.5 | I16: =G16/($C$3/100) -> 0.13255759 | J16: ='Production Guide'!C11-'Production Guide'!D11 -> 9
A17: Fruity Fran | C17: 88 | F17: FF | G17: =C17 -> 88 | H17: =G17/2 -> 44 | I17: =G17/($C$3/100) -> 0.061719935 | J17: ='Production Guide'!C12-'Production Guide'!D12 -> 4
A18: Jalapeño Holly | C18: 64 | F18: JH | G18: =C18 -> 64 | H18: =G18/2 -> 32 | I18: =G18/($C$3/100) -> 0.044887226 | J18: ='Production Guide'!C13-'Production Guide'!D13 -> 3
A19: Kickin Kay Lynne | C19: 50 | F19: KKL | G19: =C19 -> 50 | H19: =G19/2 -> 25 | I19: =G19/($C$3/100) -> 0.035068145 | J19: ='Production Guide'!C14-'Production Guide'!D14 -> 3
A20: Lauryn's Lemon Basil | C20: 54 | F20: LLB | G20: =C20 -> 54 | H20: =G20/2 -> 27 | I20: =G20/($C$3/100) -> 0.037873597 | J20: ='Production Guide'!C15-'Production Guide'!D15 -> 3
A21: Local Flavor | C21: 0 | F21: LOCAL | G21: =C21 -> 0 | H21: =G21/2 -> 0 | I21: =G21/($C$3/100) -> 0 | J21: ='Production Guide'!C16-'Production Guide'!D16 -> 0
A22: Olivia's Old South | C22: 75 | F22: OOS | G22: =C22 -> 75 | H22: =G22/2 -> 37.5 | I22: =G22/($C$3/100) -> 0.052602218 | J22: ='Production Guide'!C17-'Production Guide'!D17 -> 4
A23: Sassy Scotty | C23: 94 | F23: SS | G23: =C23 -> 94 | H23: =G23/2 -> 47 | I23: =G23/($C$3/100) -> 0.065928113 | J23: ='Production Guide'!C18-'Production Guide'!D18 -> 5
... A27: Spicy Pimento Cheese | C27: 26 | F27: SPICY PC | G27: =C27 -> 26 | H27: =G27/2 -> 13 | I27: =G27/($C$3/100) -> 0.018235435 | J27: ='Production Guide'!C22-'Production Guide'!D22 -> 2
A29: Large Bowls | F29: Flavor | G29: Total #'s | H29: Usage/100 | I29: Prep Amt
A30: Barbie Q | C30: 37 | F30: BBQ | G30: =C30 -> 37 | H30: =G30/($C$3/100) -> 0.025950427 | I30: ='Production Guide'!I6-'Production Guide'!J6 -> 2
A31: Buffalo Barclay | C31: 47 | F31: BB | G31: =C31 -> 47 | H31: =G31/($C$3/100) -> 0.032964056 | I31: ='Production Guide'!I7-'Production Guide'!J7 -> 3
A32: Classic Carol | C32: 300 | F32: CC | G32: =C32 -> 300 | H32: =G32/($C$3/100) -> 0.21040887 | I32: ='Production Guide'!I8-'Production Guide'!J8 -> 13
A33: Cranberry Kelli | C33: 132 | F33: CK | G33: =C33 -> 132 | H33: =G33/($C$3/100) -> 0.092579903 | I33: ='Production Guide'!I9-'Production Guide'!J9 -> 6
A34: Dixie Chick | C34: 48 | F34: DC | G34: =C34 -> 48 | H34: =G34/($C$3/100) -> 0.033665419 | I34: ='Production Guide'!I10-'Production Guide'!J10 -> 3
A35: Fancy Nancy | C35: 290 | F35: FN | G35: =C35 -> 290 | H35: =G35/($C$3/100) -> 0.20339524 | I35: ='Production Guide'!I11-'Production Guide'!J11 -> 13
A36: Fruity Fran | C36: 92 | F36: FF | G36: =C36 -> 92 | H36: =G36/($C$3/100) -> 0.064525387 | I36: ='Production Guide'!I12-'Production Guide'!J12 -> 4
A37: Jalapeño Holly | C37: 82 | F37: JH | G37: =C37 -> 82 | H37: =G37/($C$3/100) -> 0.057511758 | I37: ='Production Guide'!I13-'Production Guide'!J13 -> 4
A38: Kickin Kay Lynne | C38: 34 | F38: KKL | G38: =C38 -> 34 | H38: =G38/($C$3/100) -> 0.023846339 | I38: ='Production Guide'!I14-'Production Guide'!J14 -> 2
A39: Lauryn's Lemon Basil | C39: 50 | F39: LLB | G39: =C39 -> 50 | H39: =G39/($C$3/100) -> 0.035068145 | I39: ='Production Guide'!I15-'Production Guide'!J15 -> 3
A40: Local Flavor | C40: 0 | F40: LOCAL | G40: =C40 -> 0 | H40: =G40/($C$3/100) -> 0 | I40: ='Production Guide'!I16-'Production Guide'!J16 -> 0
A41: Olivia's Old South | C41: 83 | F41: OOS | G41: =C41 -> 83 | H41: =G41/($C$3/100) -> 0.058213121 | I41: ='Production Guide'!I17-'Production Guide'!J17 -> 4
... A46: Spicy Pimento Cheese | C46: 13 | F46: SPICY PC | G46: =C46 -> 13 | H46: =G46/($C$3/100) -> 0.0091177177 | I46: ='Production Guide'!I22-'Production Guide'!J22 -> 1
A48: Scoops + Sandwiches
A50: Scoop + Sandwich | F50: Flavor | G50: Total sc | H50: Total #'s | I50: Usage/100 | J50: Prep Amt
A51: Barbie Q | C51: 288 | F51: BBQ | G51: =C51 -> 288 | H51: =G51/4 -> 72 | I51: =H51/($C$3/100) -> 0.050498129 | J51: ='Production Guide'!P6-'Production Guide'!Q6 -> 4
A52: Buffalo Barclay | C52: 546 | F52: BB | G52: =C52 -> 546 | H52: =G52/4 -> 136.5 | I52: =H52/($C$3/100) -> 0.095736036 | J52: ='Production Guide'!P7-'Production Guide'!Q7 -> 9
A53: Classic Carol | C53: 1831 | F53: CC | G53: =C53 -> 1831 | H53: =G53/4 -> 457.75 | I53: =H53/($C$3/100) -> 0.32104887 | J53: ='Production Guide'!P8-'Production Guide'!Q8 -> 20
...

Sheet Future
Q1: Day After Tomorrow's Sales Forecast
X2: ='Production Guide'!R2 -> 4500
A4: Small Quick Chick | G4: Large Quick Chick | M4: Line- (Any mixed flavors not in Quick Chick) | T4: Totals
A5: Flavor | C5: Par | D5: On Hand | E5: #s to Prep | G5: Flavor | I5: Par | J5: On Hand | K5: #s to Prep | M5: Flavor | O5: Par | P5: On Hand | Q5: #s to Prep | T5: Flavor | V5: Par | W5: On Hand | X5: #s to Prep | AD5: Broccoli Lexans | AE5: =(((($X$2*1.35)/100)*('All Data'!J72/2))/'All Data'!K72) -> 2.1530938 | AF5: =ROUNDUP(AE5,0) -> 3
A6: Barbie Q | C6: =ROUNDUP(((($X$2*1.35)/100)*'All Data'!I11),0) -> 2 | E6: =IF('All Data'!I30<0,0,'All Data'!J11) -> 2 | G6: Barbie Q | I6: =ROUNDUP(((($X$2*1.35)/100)*'All Data'!H30),0) -> 2 | K6: =IF('All Data'!I30<0,0,'All Data'!I30) -> 2 | M6: Barbie Q | O6: =ROUNDUP(((($X$2*1.35)/100)*'All Data'!I51),0)+AA12 -> 4 | Q6: =IF('All Data'!J51<0,0,'All Data'!J51) -> 4 | T6: Barbie Q | V6: =(C6*0.5)+I6+O6 -> 7 | W6: =(D6*0.5)+J6+P6 -> 0 | X6: =IF((V6-W6)<0,0,(V6-W6)) -> 7 | AD6: Wet Grapes | AE6: =(((($X$2*1.35)/100)*'All Data'!J73)/'All Data'!K73) -> 1.7330889 | AF6: =ROUNDUP(AE6,0) -> 2
A7: Buffalo Barclay | C7: =ROUNDUP(((($X$2*1.35)/100)*'All Data'!I12),0) -> 3 | E7: =IF('All Data'!I31<0,0,'All Data'!J12) -> 3 | G7: Buffalo Barclay | I7: =ROUNDUP(((($X$2*1.35)/100)*'All Data'!H31),0) -> 3 | K7: =IF('All Data'!I31<0,0,'All Data'!I31) -> 3 | M7: Buffalo Barclay | O7: =ROUNDUP(((($X$2*1.35)/100)*'All Data'!I52),0)+AA13 -> 9 | Q7: =IF('All Data'!J52<0,0,'All Data'!J52) -> 9 | T7: Buffalo Barclay | V7: =(C7*0.5)+I7+O7 -> 13.5 | W7: =(D7*0.5)+J7+P7 -> 0 | X7: =IF((V7-W7)<0,0,(V7-W7)) -> 13.5 | AD7: Dry Grapes | AE7: =(((($X$2*1.35)/100)*('All Data'!J74/1.75))/'All Data'!K74) -> 2.4028584 | AF7: =ROUNDUP(AE7,0) -> 3
A8: Classic Carol | C8: =ROUNDUP(((($X$2*1.35)/100)*'All Data'!I13),0) -> 9 | E8: =IF('All Data'!I32<0,0,'All Data'!J13) -> 9 | G8: Classic Carol | I8: =ROUNDUP(((($X$2*1.35)/100)*'All Data'!H32),0) -> 13 | K8: =IF('All Data'!I32<0,0,'All Data'!I32) -> 13 | M8: Classic Carol | O8: =ROUNDUP(((($X$2*1.35)/100)*'All Data'!I53),0) -> 20 | Q8: =IF('All Data'!J53<0,0,'All Data'!J53) -> 20 | T8: Classic Carol | V8: =(C8*0.5)+I8+O8 -> 37.5 | W8: =(D8*0.5)+J8+P8 -> 0 | X8: =IF((V8-W8)<0,0,(V8-W8)) -> 37.5 | AD8: Pasta Salad | AE8: =(((($X$2*1.35)/100)*('All Data'!J75/2.5))/'All Data'!K75) -> 1.0910273 | AF8: =ROUNDUP(AE8,0) -> 2
A9: Cranberry Kelli | C9: =ROUNDUP(((($X$2*1.35)/100)*'All Data'!I14),0) -> 5 | E9: =IF('All Data'!I33<0,0,'All Data'!J14) -> 5 | G9: Cranberry Kelli | I9: =ROUNDUP(((($X$2*1.35)/100)*'All Data'!H33),0) -> 6 | K9: =IF('All Data'!I33<0,0,'All Data'!I33) -> 6 | M9: Cranberry Kelli | O9: =ROUNDUP(((($X$2*1.35)/100)*'All Data'!I54),0) -> 8 | Q9: =IF('All Data'!J54<0,0,'All Data'!J54) -> 8 | T9: Cranberry Kelli | V9: =(C9*0.5)+I9+O9 -> 16.5 | W9: =(D9*0.5)+J9+P9 -> 0 | X9: =IF((V9-W9)<0,0,(V9-W9)) -> 16.5 | AD9: GS Dressing | AE9: =AE7*0.5 -> 1.2014292 | AF9: =ROUNDUP(AE9,0) -> 2
A10: Dixie Chick | C10: =ROUNDUP(((($X$2*1.35)/100)*'All Data'!I15),0) -> 2 | E10: =IF('All Data'!I34<0,0,'All Data'!J15) -> 2 | G10: Dixie Chick | I10: =ROUNDUP(((($X$2*1.35)/100)*'All Data'!H34),0) -> 3 | K10: =IF('All Data'!I34<0,0,'All Data'!I34) -> 3 | M10: Dixie Chick | O10: =ROUNDUP(((($X$2*1.35)/100)*'All Data'!I55),0) -> 5 | Q10: =IF('All Data'!J55<0,0,'All Data'!J55) -> 5 | T10: Dixie Chick | V10: =(C10*0.5)+I10+O10 -> 9 | W10: =(D10*0.5)+J10+P10 -> 0 | X10: =IF((V10-W10)<0,0,(V10-W10)) -> 9
A11: Fancy Nancy | C11: =ROUNDUP(((($X$2*1.35)/100)*'All Data'!I16),0) -> 9 | E11: =IF('All Data'!I35<0,0,'All Data'!J16) -> 9 | G11: Fancy Nancy | I11: =ROUNDUP(((($X$2*1.35)/100)*'All Data'!H35),0) -> 13 | K11: =IF('All Data'!I35<0,0,'All Data'!I35) -> 13 | M11: Fancy Nancy | O11: =ROUNDUP(((($X$2*1.35)/100)*'All Data'!I56),0) -> 22 | Q11: =IF('All Data'!J56<0,0,'All Data'!J56) -> 22 | T11: Fancy Nancy | V11: =(C11*0.5)+I11+O11 -> 39.5 | W11: =(D11*0.5)+J11+P11 -> 0 | X11: =IF((V11-W11)<0,0,(V11-W11)) -> 39.5
A12: Fruity Fran | C12: =ROUNDUP(((($X$2*1.35)/100)*'All Data'!I17),0) -> 4 | E12: =IF('All Data'!I36<0,0,'All Data'!J17) -> 4 | G12: Fruity Fran | I12: =ROUNDUP(((($X$2*1.35)/100)*'All Data'!H36),0) -> 4 | K12: =IF('All Data'!I36<0,0,'All Data'!I36) -> 4 | M12: Fruity Fran | O12: =ROUNDUP(((($X$2*1.35)/100)*'All Data'!I57),0) -> 9 | Q12: =IF('All Data'!J57<0,0,'All Data'!J57) -> 9 | T12: Fruity Fran | V12: =(C12*0.5)+I12+O12 -> 15 | W12: =(D12*0.5)+J12+P12 -> 0 | X12: =IF((V12-W12)<0,0,(V12-W12)) -> 15
A13: Jalapeño Holly | C13: =ROUNDUP(((($X$2*1.35)/100)*'All Data'!I18),0) -> 3 | E13: =IF('All Data'!I37<0,0,'All Data'!J18) -> 3 | G13: Jalapeño Holly | I13: =ROUNDUP(((($X$2*1.35)/100)*'All Data'!H37),0) -> 4 | K13: =IF('All Data'!I37<0,0,'All Data'!I37) -> 4 | M13: Jalapeño Holly | O13: =ROUNDUP(((($X$2*1.35)/100)*'All Data'!I58),0)+AA13 -> 9 | Q13: =IF('All Data'!J58<0,0,'All Data'!J58) -> 9 | T13: Jalapeño Holly | V13: =(C13*0.5)+I13+O13 -> 14.5 | W13: =(D13*0.5)+J13+P13 -> 0 | X13: =IF((V13-W13)<0,0,(V13-W13)) -> 14.5 | AA13: ='Production Guide'!K48 -> 3
A14: Kickin Kay Lynne | C14: =ROUNDUP(((($X$2*1.35)/100)*'All Data'!I19),0) -> 3 | E14: =IF('All Data'!I38<0,0,'All Data'!J19) -> 3 | G14: Kickin Kay Lynne | I14: =ROUNDUP(((($X$2*1.35)/100)*'All Data'!H38),0) -> 2 | K14: =IF('All Data'!I38<0,0,'All Data'!I38) -> 2 | M14: Kickin Kay Lynne | O14: =ROUNDUP(((($X$2*1.35)/100)*'All Data'!I59),0) -> 6 | Q14: =IF('All Data'!J59<0,0,'All Data'!J59) -> 6 | T14: Kickin Kay Lynne | V14: =(C14*0.5)+I14+O14 -> 9.5 | W14: =(D14*0.5)+J14+P14 -> 0 | X14: =IF((V14-W14)<0,0,(V14-W14)) -> 9.5
A15: Lauryn's L. Basil | C15: =ROUNDUP(((($X$2*1.35)/100)*'All Data'!I20),0) -> 3 | E15: =IF('All Data'!I39<0,0,'All Data'!J20) -> 3 | G15: Lauryn's L. Basil | I15: =ROUNDUP(((($X$2*1.35)/100)*'All Data'!H39),0) -> 3 | K15: =IF('All Data'!I39<0,0,'All Data'!I39) -> 3 | M15: Lauryn's L. Basil | O15: =ROUNDUP(((($X$2*1.35)/100)*'All Data'!I60),0) -> 5 | Q15: =IF('All Data'!J60<0,0,'All Data'!J60) -> 5 | T15: Lauryn's L. Basil | V15: =(C15*0.5)+I15+O15 -> 9.5 | W15: =(D15*0.5)+J15+P15 -> 0 | X15: =IF((V15-W15)<0,0,(V15-W15)) -> 9.5
A16: Local Flavor | C16: =ROUNDUP(((($X$2*1.35)/100)*'All Data'!I21),0) -> 0 | E16: =IF('All Data'!I40<0,0,'All Data'!J21) -> 0 | G16: Local Flavor | I16: =ROUNDUP(((($X$2*1.35)/100)*'All Data'!H40),0) -> 0 | K16: =IF('All Data'!I40<0,0,'All Data'!I40) -> 0 | M16: Local Flavor | O16: =ROUNDUP(((($X$2*1.35)/100)*'All Data'!I61),0) -> 0 | Q16: =IF('All Data'!J61<0,0,'All Data'!J61) -> 0 | T16: Local Flavor | V16: =(C16*0.5)+I16+O16 -> 0 | W16: =(D16*0.5)+J16+P16 -> 0 | X16: =IF((V16-W16)<0,0,(V16-W16)) -> 0
A17: Olivia's Old South | C17: =ROUNDUP(((($X$2*1.35)/100)*'All Data'!I22),0) -> 4 | E17: =IF('All Data'!I41<0,0,'All Data'!J22) -> 4 | G17: Olivia's Old South | I17: =ROUNDUP(((($X$2*1.35)/100)*'All Data'!H41),0) -> 4 | K17: =IF('All Data'!I41<0,0,'All Data'!I41) -> 4 | M17: Olivia's Old South | O17: =ROUNDUP(((($X$2*1.35)/100)*'All Data'!I62),0) -> 9 | Q17: =IF('All Data'!J62<0,0,'All Data'!J62) -> 9 | T17: Olivia's Old South | V17: =(C17*0.5)+I17+O17 -> 15 | W17: =(D17*0.5)+J17+P17 -> 0 | X17: =IF((V17-W17)<0,0,(V17-W17)) -> 15
A18: Sassy Scotty | C18: =ROUNDUP(((($X$2*1.35)/100)*'All Data'!I23),0) -> 5 | E18: =IF('All Data'!I42<0,0,'All Data'!J23) -> 5 | G18: Sassy Scotty | I18: =ROUNDUP(((($X$2*1.35)/100)*'All Data'!H42),0) -> 5 | K18: =IF('All Data'!I42<0,0,'All Data'!I42) -> 5 | M18: Sassy Scotty | O18: =ROUNDUP(((($X$2*1.35)/100)*'All Data'!I63),0)+AA13 -> 13 | Q18: =IF('All Data'!J63<0,0,'All Data'!J63) -> 13 | T18: Sassy Scotty | V18: =(C18*0.5)+I18+O18 -> 20.5 | W18: =(D18*0.5)+J18+P18 -> 0 | X18: =IF((V18-W18)<0,0,(V18-W18)) -> 20.5
A19: LTO | C19: =ROUNDUP(((($X$2*1.35)/100)*'All Data'!I24),0) -> 3 | E19: =IF('All Data'!I43<0,0,'All Data'!J24) -> 3 | G19: LTO | I19: =ROUNDUP(((($X$2*1.35)/100)*'All Data'!H43),0) -> 2 | K19: =IF('All Data'!I43<0,0,'All Data'!I43) -> 2 | M19: LTO | O19: =ROUNDUP(((($X$2*1.35)/100)*'All Data'!I64),0) -> 4 | Q19: =IF('All Data'!J64<0,0,'All Data'!J64) -> 4 | T19: LTO | V19: =(C19*0.5)+I19+O19 -> 7.5 | W19: =(D19*0.5)+J19+P19 -> 0 | X19: =IF((V19-W19)<0,0,(V19-W19)) -> 7.5
A20: Egg Salad | C20: =ROUNDUP(((($X$2*1.35)/100)*'All Data'!I25),0) -> 3 | E20: =IF('All Data'!I44<0,0,'All Data'!J25) -> 3 | G20: Egg Salad | I20: =ROUNDUP(((($X$2*1.35)/100)*'All Data'!H44),0) -> 2 | K20: =IF('All Data'!I44<0,0,'All Data'!I44) -> 2 | M20: Egg Salad | O20: =ROUNDUP(((($X$2*1.35)/100)*'All Data'!I65),0) -> 4 | Q20: =IF('All Data'!J65<0,0,'All Data'!J65) -> 4 | T20: Egg Salad | V20: =(C20*0.5)+I20+O20 -> 7.5 | W20: =(D20*0.5)+J20+P20 -> 0 | X20: =IF((V20-W20)<0,0,(V20-W20)) -> 7.5
A21: Pimento Cheese | C21: =ROUNDUP(((($X$2*1.35)/100)*'All Data'!I26),0) -> 4 | E21: =IF('All Data'!I45<0,0,'All Data'!J26) -> 4 | G21: Pimento Cheese | I21: =ROUNDUP(((($X$2*1.35)/100)*'All Data'!H45),0) -> 3 | K21: =IF('All Data'!I45<0,0,'All Data'!I45) -> 3 | M21: Pimento Cheese | O21: =ROUNDUP(((($X$2*1.35)/100)*'All Data'!I66),0) -> 3 | Q21: =IF('All Data'!J66<0,0,'All Data'!J66) -> 3 | T21: Pimento Cheese | V21: =(C21*0.5)+I21+O21 -> 8 | W21: =(D21*0.5)+J21+P21 -> 0 | X21: =IF((V21-W21)<0,0,(V21-W21)) -> 8
A22: Spicy P. Cheese | C22: =ROUNDUP(((($X$2*1.35)/100)*'All Data'!I27),0) -> 2 | E22: =IF('All Data'!I46<0,0,'All Data'!J27) -> 2 | G22: Spicy P. Cheese | I22: =ROUNDUP(((($X$2*1.35)/100)*'All Data'!H46),0) -> 1 | K22: =IF('All Data'!I46<0,0,'All Data'!I46) -> 1 | M22: Spicy P. Cheese | O22: =ROUNDUP(((($X$2*1.35)/100)*'All Data'!I67),0) -> 2 | Q22: =IF('All Data'!J67<0,0,'All Data'!J67) -> 2 | T22: Spicy P. Cheese | V22: =(C22*0.5)+I22+O22 -> 4 | W22: =(D22*0.5)+J22+P22 -> 0 | X22: =IF((V22-W22)<0,0,(V22-W22)) -> 4
T24: Total Classic Carol | W24: =SUM(X6:Y19)-X14 -> 205
G25: Sides | I25: Daily Par (in 1/2 pans)
G26: Broccoli Salad | I26: =((($X$2*1.35)/100)*'All Data'!J72)/'All Data'!K72 -> 4.3061876
G27: Fresh Fruit | I27: =((($X$2*1.35)/100)*'All Data'!J73)/'All Data'!K73 -> 1.7330889
G28: Grape Salad | I28: =((($X$2*1.35)/100)*'All Data'!J74)/'All Data'!K74 -> 4.2050022
G29: Pasta Salad | I29: =((($X$2*1.35)/100)*'All Data'!J75)/'All Data'!K75 -> 2.7275683
G32: Proj. Sales | H32: Cut Broccoli Lexis | I32: Dry | J32: Wet | K32: Batches of GrapeSaladDressing | L32: Pimento Cheese Batches | M32: Pasta
I33: Grape | J33: Grape* | M33: Salad Batches
I34: Lexis | J34: Lexis
G35: 2000 | H35: 2 | I35: 1 | J35: .75 | K35: 1 | L35: 1 | M35: 1
G36: 3000 | H36: 2 | I36: 2 | J36: 1 | K36: 1 | L36: 1 | M36: 1
G37: 4000 | H37: 3 | I37: 2 | J37: 1.5 | K37: 1 | L37: 2 | M37: 1
G38: 5000 | H38: 4 | I38: 3 | J38: 1.5 | K38: 2 | L38: 2 | M38: 1
G39: 6000 | H39: 4 | I39: 3 | J39: 2 | K39: 2 | L39: 2 | M39: 1
G40: 7000 | H40: 5 | I40: 4 | J40: 2 | K40: 2 | L40: 2 | M40: 2
G41: 8000 | H41: 6 | I41: 5 | J41: 2.5 | K41: 3 | L41: 3 | M41: 2
G42: 9000 | H42: 6 | I42: 5 | J42: 3 | K42: 3 | L42: 3 | M42: 2
G43: 10,000 | H43: 7 | I43: 6 | J43: 3 | K43: 3 | L43: 3 | M43: 2
G44: 11,000 | H44: 8 | I44: 6 | J44: 3.5 | K44: 3 | L44: 3 | M44: 2
