Workbook

Sheet Count Sheet 
D2: Count Sheet
B5: Quick Chick | G5: Line | K5: Waste
B7: Flavor | D7: SM | E7: LG | G7: Flavor | K7: Flavor
B8: Barbie Q | G8: Barbie Q | K8: BBQ
B9: Buffalo Barclay | G9: Buffalo Barclay | K9: BB
B10: Classic Carol | G10: Classic Carol | K10: CC
B11: Cranberry Kelli | G11: Cranberry Kelli | K11: CK
B12: Dixie Chick | G12: Dixie Chick | K12: DC
B13: Fancy Nancy | G13: Fancy Nancy | K13: FN
B14: Fruity Fran | G14: Fruity Fran | K14: FF
B15: Jalapeño Holly | G15: Jalapeño Holly | K15: JH
B16: Kickin Kay Lynne | G16: Kickin Kay Lynne | K16: KKL
B17: Lauryn's L. Basil | G17: Lauryn's L. Basil | K17: LLB
B18: Local Flavor | G18: Local Flavor | K18: LOCAL
B19: Olivia's Old South | G19: Olivia's Old South | K19: OOS
... B29: Count all chicken salad Quick Chicks by container. Count Side Items by the 1/2 pan. | G29: Count mixed flavors in the line coolers, reach-ins, and walk-in by the pound. Count side items by the 1/2 pan. | K29: Count all waste in pounds.
C31: Todays Date: | H31: Color to Discard:

Sheet Production Guide
A1: Next Day's Sales Forecast | K1: Day After Tomorrow's Sales Forecast
E2: 4500 | R2: 4500
A4: Small Quick Chick | G4: Large Quick Chick | N4: Line- (Any mixed flavors not in Quick Chick) | U4: Totals
A5: Flavor | C5: Par | D5: On Hand | E5: QC's to Prep | G5: Flavor | I5: Par | J5: On Hand | K5: QC's to Prep | N5: Flavor | P5: Par | Q5: On Hand | R5: #s to Prep | U5: Flavor | W5: Par | X5: On Hand | Y5: #s to Prep
A6: Barbie Q | C6: 2 | D6: 0 | E6: =IF('All Data'!J11<0,0,'All Data'!J11) | G6: Barbie Q | I6: 2 | J6: 0 | K6: =IF('All Data'!I30<0,0,'All Data'!I30) | N6: Barbie Q | P6: 2 | Q6: 0 | R6: =IF('All Data'!J51<0,0,'All Data'!J51) | U6: Barbie Q | W6: =(C6*0.5)+I6+P6 | X6: =(D6*0.5)+J6+Q6 | Y6: =ROUNDUP(IF((W6-X6)<0,0,(W6-X6))+C25,0)
A7: Buffalo Barclay | C7: 3 | D7: 3 | E7: =IF('All Data'!J12<0,0,'All Data'!J12) | G7: Buffalo Barclay | I7: 2 | J7: 3 | K7: =IF('All Data'!I31<0,0,'All Data'!I31) | N7: Buffalo Barclay | P7: 3 | Q7: 0 | R7: =IF('All Data'!J52<0,0,'All Data'!J52) | U7: Buffalo Barclay | W7: =(C7*0.5)+I7+P7 | X7: =(D7*0.5)+J7+Q7 | Y7: =ROUNDUP(IF((W7-X7)<0,0,(W7-X7))+C26,0)
A8: Classic Carol | C8: 9 | D8: 0 | E8: =IF('All Data'!J13<0,0,'All Data'!J13) | G8: Classic Carol | I8: 12 | J8: 0 | K8: =IF('All Data'!I32<0,0,'All Data'!I32) | N8: Classic Carol | P8: 7 | Q8: 0 | R8: =IF('All Data'!J53<0,0,'All Data'!J53) | U8: Classic Carol | W8: =(C8*0.5)+I8+P8 | X8: =(D8*0.5)+J8+Q8 | Y8: =ROUNDUP(IF((W8-X8)<0,0,(W8-X8))+C27,0)
A9: Cranberry Kelli | C9: 6 | D9: 0 | E9: =IF('All Data'!J14<0,0,'All Data'!J14) | G9: Cranberry Kelli | I9: 6 | J9: 0 | K9: =IF('All Data'!I33<0,0,'All Data'!I33) | N9: Cranberry Kelli | P9: 4 | Q9: 0 | R9: =IF('All Data'!J54<0,0,'All Data'!J54) | U9: Cranberry Kelli | W9: =(C9*0.5)+I9+P9 | X9: =(D9*0.5)+J9+Q9 | Y9: =ROUNDUP(IF((W9-X9)<0,0,(W9-X9))+C28,0)
A10: Dixie Chick | C10: 4 | D10: 0 | E10: =IF('All Data'!J15<0,0,'All Data'!J15) | G10: Dixie Chick | I10: 4 | J10: 0 | K10: =IF('All Data'!I34<0,0,'All Data'!I34) | N10: Dixie Chick | P10: 3 | Q10: 0 | R10: =IF('All Data'!J55<0,0,'All Data'!J55) | U10: Dixie Chick | W10: =(C10*0.5)+I10+P10 | X10: =(D10*0.5)+J10+Q10 | Y10: =ROUNDUP(IF((W10-X10)<0,0,(W10-X10))+C29,0)
A11: Fancy Nancy | C11: 9 | D11: 0 | E11: =IF('All Data'!J16<0,0,'All Data'!J16) | G11: Fancy Nancy | I11: 13 | J11: 0 | K11: =IF('All Data'!I35<0,0,'All Data'!I35) | N11: Fancy Nancy | P11: 7 | Q11: 0 | R11: =IF('All Data'!J56<0,0,'All Data'!J56) | U11: Fancy Nancy | W11: =(C11*0.5)+I11+P11 | X11: =(D11*0.5)+J11+Q11 | Y11: =ROUNDUP(IF((W11-X11)<0,0,(W11-X11))+C30,0)
A12: Fruity Fran | C12: 4 | D12: 0 | E12: =IF('All Data'!J17<0,0,'All Data'!J17) | G12: Fruity Fran | I12: 4 | J12: 0 | K12: =IF('All Data'!I36<0,0,'All Data'!I36) | N12: Fruity Fran | P12: 3 | Q12: 0 | R12: =IF('All Data'!J57<0,0,'All Data'!J57) | U12: Fruity Fran | W12: =(C12*0.5)+I12+P12 | X12: =(D12*0.5)+J12+Q12 | Y12: =ROUNDUP(IF((W12-X12)<0,0,(W12-X12))+C31,0)
A13: Jalapeño Holly | C13: 5 | D13: 0 | E13: =IF('All Data'!J18<0,0,'All Data'!J18) | G13: Jalapeño Holly | I13: 5 | J13: 0 | K13: =IF('All Data'!I37<0,0,'All Data'!I37) | N13: Jalapeño Holly | P13: 4 | Q13: 0 | R13: =IF('All Data'!J58<0,0,'All Data'!J58) | U13: Jalapeño Holly | W13: =(C13*0.5)+I13+P13 | X13: =(D13*0.5)+J13+Q13 | Y13: =ROUNDUP(IF((W13-X13)<0,0,(W13-X13))+C32,0)
A14: Kickin Kay Lynne | C14: 2 | D14: 0 | E14: =IF('All Data'!J19<0,0,'All Data'!J19) | G14: Kickin Kay Lynne | I14: 2 | J14: 0 | K14: =IF('All Data'!I38<0,0,'All Data'!I38) | N14: Kickin Kay Lynne | P14: 3 | Q14: 0 | R14: =IF('All Data'!J59<0,0,'All Data'!J59) | U14: Kickin Kay Lynne | W14: =(C14*0.5)+I14+P14 | X14: =(D14*0.5)+J14+Q14 | Y14: =ROUNDUP(IF((W14-X14)<0,0,(W14-X14))+C33,0)
A15: Lauryn's L. Basil | C15: 3 | D15: 0 | E15: =IF('All Data'!J20<0,0,'All Data'!J20) | G15: Lauryn's L. Basil | I15: 3 | J15: 0 | K15: =IF('All Data'!I39<0,0,'All Data'!I39) | N15: Lauryn's L. Basil | P15: 3 | Q15: 0 | R15: =IF('All Data'!J60<0,0,'All Data'!J60) | U15: Lauryn's L. Basil | W15: =(C15*0.5)+I15+P15 | X15: =(D15*0.5)+J15+Q15 | Y15: =ROUNDUP(IF((W15-X15)<0,0,(W15-X15))+C34,0)
A16: Local Flavor | C16: =ROUNDUP(((($E$2*1.35)/100)*'All Data'!I21),0) | D16: 0 | E16: =IF('All Data'!J21<0,0,'All Data'!J21) | G16: Local Flavor | I16: =ROUNDUP(((($E$2*1.35)/100)*'All Data'!H40),0) | J16: 0 | K16: =IF('All Data'!I40<0,0,'All Data'!I40) | N16: Local Flavor | P16: =ROUNDUP(((($E$2*1.35)/100)*'All Data'!I61),0) | Q16: 0 | R16: =IF('All Data'!J61<0,0,'All Data'!J61) | U16: Local Flavor | W16: =(C16*0.5)+I16+P16 | X16: =(D16*0.5)+J16+Q16 | Y16: =ROUNDUP(IF((W16-X16)<0,0,(W16-X16))+C35,0)
A17: Olivia's Old South | C17: 4 | D17: 0 | E17: =IF('All Data'!J22<0,0,'All Data'!J22) | G17: Olivia's Old South | I17: 4 | J17: 0 | K17: =IF('All Data'!I41<0,0,'All Data'!I41) | N17: Olivia's Old South | P17: 3 | Q17: 0 | R17: =IF('All Data'!J62<0,0,'All Data'!J62) | U17: Olivia's Old South | W17: =(C17*0.5)+I17+P17 | X17: =(D17*0.5)+J17+Q17 | Y17: =ROUNDUP(IF((W17-X17)<0,0,(W17-X17))+C36,0)
A18: Sassy Scotty | C18: 5 | D18: 0 | E18: =IF('All Data'!J23<0,0,'All Data'!J23) | G18: Sassy Scotty | I18: 5 | J18: 0 | K18: =IF('All Data'!I42<0,0,'All Data'!I42) | N18: Sassy Scotty | P18: 4 | Q18: 0 | R18: =IF('All Data'!J63<0,0,'All Data'!J63) | U18: Sassy Scotty | W18: =(C18*0.5)+I18+P18 | X18: =(D18*0.5)+J18+Q18 | Y18: =ROUNDUP(IF((W18-X18)<0,0,(W18-X18))+C37,0)
A19: LTO | C19: =ROUNDUP(((($E$2*1.35)/100)*'All Data'!I24),0) | D19: 0 | E19: =IF('All Data'!J24<0,0,'All Data'!J24) | G19: LTO | I19: =ROUNDUP(((($E$2*1.35)/100)*'All Data'!H43),0) | J19: 0 | K19: =IF('All Data'!I43<0,0,'All Data'!I43) | N19: LTO | P19: =ROUNDUP(((($E$2*1.35)/100)*'All Data'!I64),0) | Q19: 0 | R19: =IF('All Data'!J64<0,0,'All Data'!J64) | U19: LTO | W19: =(C19*0.5)+I19+P19 | X19: =(D19*0.5)+J19+Q19 | Y19: =ROUNDUP(IF((W19-X19)<0,0,(W19-X19))+C38,0)
A20: Egg Salad | C20: =ROUNDUP(((($E$2*1.35)/100)*'All Data'!I25),0) | D20: 0 | E20: =IF('All Data'!J25<0,0,'All Data'!J25) | G20: Egg Salad | I20: =ROUNDUP(((($E$2*1.35)/100)*'All Data'!H44),0) | J20: 0 | K20: =IF('All Data'!I44<0,0,'All Data'!I44) | N20: Egg Salad | P20: =ROUNDUP(((($E$2*1.35)/100)*'All Data'!I65),0) | Q20: 0 | R20: =IF('All Data'!J65<0,0,'All Data'!J65) | U20: Egg Salad | W20: =(C20*0.5)+I20+P20 | X20: =(D20*0.5)+J20+Q20 | Y20: =ROUNDUP(IF((W20-X20)<0,0,(W20-X20))+C39,0)
A21: Pimento Cheese | C21: =ROUNDUP(((($E$2*1.35)/100)*'All Data'!I26),0) | D21: 0 | E21: =IF('All Data'!J26<0,0,'All Data'!J26) | G21: Pimento Cheese | I21: =ROUNDUP(((($E$2*1.35)/100)*'All Data'!H45),0) | J21: 0 | K21: =IF('All Data'!I45<0,0,'All Data'!I45) | N21: Pimento Cheese | P21: =ROUNDUP(((($E$2*1.35)/100)*'All Data'!I66),0) | Q21: 0 | R21: =IF('All Data'!J66<0,0,'All Data'!J66) | U21: Pimento Cheese | W21: =(C21*0.5)+I21+P21 | X21: =(D21*0.5)+J21+Q21 | Y21: =ROUNDUP(IF((W21-X21)<0,0,(W21-X21))+C40,0)
A22: Spicy P. Cheese | C22: =ROUNDUP(((($E$2*1.35)/100)*'All Data'!I27),0) | D22: 0 | E22: =IF('All Data'!J27<0,0,'All Data'!J27) | G22: Spicy P. Cheese | I22: =ROUNDUP(((($E$2*1.35)/100)*'All Data'!H46),0) | J22: 0 | K22: =IF('All Data'!I46<0,0,'All Data'!I46) | N22: Spicy P. Cheese | P22: =ROUNDUP(((($E$2*1.35)/100)*'All Data'!I67),0) | Q22: 0 | R22: =IF('All Data'!J67<0,0,'All Data'!J67) | U22: Spicy P. Cheese | W22: =(C22*0.5)+I22+P22 | X22: =(D22*0.5)+J22+Q22 | Y22: =ROUNDUP(IF((W22-X22)<0,0,(W22-X22))+C41,0)
A24: Tomorrow's Catering #'s
A25: Barbie Q | G25: Side Item | I25: Par | J25: On Hand | K25: 1/2 Pan Prep
A26: Buffalo Barclay | G26: Broccoli Salad | I26: =(((($E$2*1.35)/100)*'All Data'!J72)/'All Data'!K72) | K26: =IF(((I26-J26+C42)<0),0,(I26-J26+(C42/5.63))) | N26: Broccoli salad yields (2) 1/2 pans. Pasta Salad yields (3) 1/2 pans.
A27: Classic Carol | G27: Fresh Fruit | I27: =(((($E$2*1.35)/100)*'All Data'!J73)/'All Data'!K73) | K27: =IF(((I27-J27+C43)<0),0,(I27-J27+(C43/8.785)))
A28: Cranberry Kelli | G28: Grape Salad | I28: =(((($E$2*1.35)/100)*'All Data'!J74)/'All Data'!K74) | K28: =IF(((I28-J28+C44)<0),0,(I28-J28+(C44/8.25)))
A29: Dixie Chick | G29: Pasta Salad | I29: =(((($E$2*1.35)/100)*'All Data'!J75)/'All Data'!K75) | K29: =IF(((I29-J29+C45)<0),0,(I29-J29+(C45/6.79)))
A30: Fancy Nancy
A31: Fruity Fran
A32: Jalapeño Holly | G32: Produce Item | I32: Par
A33: Kickin Kay Lynne | G33: Broccoli Lexans | I33: =Future!I26/2
A34: Lauryn's L. Basil | G34: Dried Grape Lexans | I34: =Future!I28/2
A35: Local Flavor
A36: Olivia's Old South | G36: Salads | I36: Par
A37: Sassy Scotty | G37: Classic Salads | I37: ='All Data'!G85
A38: LTO | G38: Seasonal Salads | I38: ='All Data'!G86
A39: Egg Salad
A40: Pimento Cheese
A41: Spicy P. Cheese
A42: Broccoli Salad
...

Sheet 2 Prep Cooks
B1: Date:
B3: Today's Forecast: | E3: ='Production Guide'!E2
A6: Daily Production List | G6: Item | H6: Prep
G7: Broccoli Lexis | H7: =Future!AE5
G8: Wet Grape Lexis | H8: =Future!AE6
A9: SM | B9: LG | C9: Cook | D9: Flavor | E9: #'s to Prep | G9: Dry Grape Lexis | H9: =Future!AE7
A10: ='Production Guide'!E8 | B10: ='Production Guide'!K8 | C10: C1 | D10: Classic Carol | E10: ='Production Guide'!Y8 | G10: Pasta Salad Batches | H10: =Future!AE8
A11: ='Production Guide'!E9 | B11: ='Production Guide'!K9 | C11: C1 | D11: Cranberry Kelli | E11: ='Production Guide'!Y9 | G11: Grape Salad Dressing | H11: =Future!AF9
A12: ='Production Guide'!E17 | B12: ='Production Guide'!K17 | C12: C1 | D12: Olivia's Old South | E12: ='Production Guide'!Y17
A13: ='Production Guide'!E12 | B13: ='Production Guide'!K12 | C13: C1 | D13: Fruity Fran | E13: ='Production Guide'!Y12 | G13: Salads | H13: Par
A14: ='Production Guide'!E19 | B14: ='Production Guide'!K19 | C14: C1 | D14: LTO | E14: ='Production Guide'!Y19 | G14: Classic Salads | H14: ='All Data'!G85
A15: ='Production Guide'!E10 | B15: ='Production Guide'!K10 | C15: C1 | D15: Dixie Chick | E15: ='Production Guide'!Y10 | G15: Seasonal Salads | H15: ='All Data'!G86
A16: ='Production Guide'!E16 | B16: ='Production Guide'!K16 | C16: C1 | D16: Local Flavor | E16: ='Production Guide'!Y16
A17: ='Production Guide'!E15 | B17: ='Production Guide'!K15 | C17: C1 | D17: Lauryn's Lemon Basil | E17: ='Production Guide'!Y15 | F17: KKL
A18: ='Production Guide'!E18 | B18: ='Production Guide'!K18 | C18: C2 | D18: Sassy Scotty | E18: ='Production Guide'!Y18 | F18: =E22/3
A19: ='Production Guide'!E11 | B19: ='Production Guide'!K11 | C19: C2 | D19: Fancy Nancy | E19: ='Production Guide'!Y11
A20: ='Production Guide'!E7 | B20: ='Production Guide'!K7 | C20: C2 | D20: Buffalo Barclay | E20: ='Production Guide'!Y7 | F20: =E22/3
A21: ='Production Guide'!E13 | B21: ='Production Guide'!K13 | C21: C2 | D21: Jalapeño Holly | E21: ='Production Guide'!Y13 | F21: =E22/3
A22: ='Production Guide'!E14 | B22: ='Production Guide'!K14 | C22: C2 | D22: Kickin Kay Lynne | E22: =MROUND('Production Guide'!Y14,3)
A23: ='Production Guide'!E6 | B23: ='Production Guide'!K6 | C23: C2 | D23: Barbie Q | E23: ='Production Guide'!Y6
A24: ='Production Guide'!E21 | B24: ='Production Guide'!K21 | C24: C2 | D24: Pimento Cheese | E24: ='Production Guide'!Y21
A25: ='Production Guide'!E22 | B25: ='Production Guide'!K22 | C25: C2 | D25: Spicy Pimento Cheese | E25: ='Production Guide'!Y22
A26: ='Production Guide'!E20 | B26: ='Production Guide'!K20 | C26: C2 | D26: Egg Salad | E26: ='Production Guide'!Y20
D27: Total Mixed Flavors | E27: =SUM(E10:E23)-E22
C29: Cook | D29: Ingredient | E29: Cups to Prep | G29: Salad Item Prep
C30: C2 | D30: Apples | E30: =(E19+E13)*0.25 | G30: Salad Mix
C31: C2 | D31: Eggs | E31: =E12*0.25 | G31: Strawberries
C32: C2 | D32: Onions | E32: =E15*0.25 | G32: Unpeeled Apples
C33: C2 | D33: Bacon | E33: =(E18*0.25)+(E16*0.25) | G33: Cucumbers
C34: C2 | D34: Pineapple | E34: =E13*0.25
D35: Side | E35: 1/2 Pans | G35: Classic Carol for Tomorrow
D36: Broccoli Salad | E36: ='Production Guide'!K26 | G36: =Future!W24
D37: Fresh Fruit | E37: ='Production Guide'!K27 | G37: C1- seasonal salad ingred, strawberries for fresh fruit & pasta salad
D38: Grape Salad | E38: ='Production Guide'!K28
D39: Pasta Salad | E39: ='Production Guide'!K29
C40: Broccoli salad yields (2) 1/2 pans. Pasta Salad yields (3) 1/2 pans. | G40: C2 & C3- sinks, sanitizer bucket, sanitize work stations, bowls & lids
A42: Sandwich line will quick chick the flavors highlighted. | G42: C4- Temperature logs

Sheet 3 Prep Cooks
B1: Date:
B3: Today's Forecast: | E3: ='Production Guide'!E2
A6: Daily Production List | G6: Item | H6: Prep
G7: Broccoli Lexis | H7: =Future!AE5
G8: Wet Grape Lexis | H8: =Future!AE6
A9: SM | B9: QC | C9: Cook | D9: Flavor | E9: #'s to Prep | G9: Dry Grape Lexis | H9: =Future!AE7
A10: ='Production Guide'!E8 | B10: ='Production Guide'!K8 | C10: C1 | D10: Classic Carol | E10: ='Production Guide'!Y8 | G10: Pasta Salad Batches | H10: =Future!AE8
A11: ='Production Guide'!E17 | B11: ='Production Guide'!K17 | C11: C1 | D11: Olivia's Old South | E11: ='Production Guide'!Y17 | G11: Grape Salad Dressing | H11: =Future!AF9
A12: ='Production Guide'!E12 | B12: ='Production Guide'!K12 | C12: C1 | D12: Fruity Fran | E12: ='Production Guide'!Y12
A13: ='Production Guide'!E19 | B13: ='Production Guide'!K19 | C13: C1 | D13: LTO | E13: ='Production Guide'!Y19 | G13: Salads | H13: Par
A14: ='Production Guide'!E6 | B14: ='Production Guide'!K6 | C14: C1 | D14: Barbie Q | E14: ='Production Guide'!Y6 | G14: Classic Salads | H14: ='All Data'!G85
A15: ='Production Guide'!E10 | B15: ='Production Guide'!K10 | C15: C1 | D15: Dixie Chick | E15: ='Production Guide'!Y10 | G15: Seasonal Salads | H15: ='All Data'!G86
A16: ='Production Guide'!E9 | B16: ='Production Guide'!K9 | C16: C2 | D16: Cranberry Kelli | E16: ='Production Guide'!Y9
A17: ='Production Guide'!E11 | B17: ='Production Guide'!K11 | C17: C2 | D17: Fancy Nancy | E17: ='Production Guide'!Y11
A18: ='Production Guide'!E16 | B18: ='Production Guide'!K16 | C18: C2 | D18: Local Flavor | E18: ='Production Guide'!Y16
A19: ='Production Guide'!E15 | B19: ='Production Guide'!K15 | C19: C2 | D19: Lauryn's Lemon Basil | E19: ='Production Guide'!Y15
A20: ='Production Guide'!E21 | B20: ='Production Guide'!K21 | C20: C2 | D20: Pimento Cheese | E20: ='Production Guide'!Y21
A21: ='Production Guide'!E22 | B21: ='Production Guide'!K22 | C21: C2 | D21: Spicy Pimento Cheese | E21: ='Production Guide'!Y22 | F21: KKL
A22: ='Production Guide'!E18 | B22: ='Production Guide'!K18 | C22: C3 | D22: Sassy Scotty | E22: ='Production Guide'!Y18 | F22: =E25/3
A23: ='Production Guide'!E13 | B23: ='Production Guide'!K13 | C23: C3 | D23: Jalapeño Holly | E23: ='Production Guide'!Y13 | F23: =E25/3
A24: ='Production Guide'!E7 | B24: ='Production Guide'!K7 | C24: C3 | D24: Buffalo Barclay | E24: ='Production Guide'!Y7 | F24: =E25/3
A25: ='Production Guide'!E14 | B25: ='Production Guide'!K14 | C25: C3 | D25: Kickin Kay Lynne | E25: =MROUND('Production Guide'!Y14,3)
A26: ='Production Guide'!E20 | B26: ='Production Guide'!K20 | C26: C3 | D26: Egg Salad | E26: ='Production Guide'!Y20
D27: Total Mixed Flavors | E27: =SUM(E10:E25)-E20-E21-E25
G28: Salad Item Prep
C29: Cook | D29: Ingredient | E29: Cups to Prep | G29: Salad Mix
C30: C1 | D30: Apples | E30: =(E17+E12)*0.25 | G30: Strawberries
C31: C1 | D31: Eggs | E31: =E11*0.25 | G31: Unpeeled Apples
C32: C1 | D32: Onions | E32: =E15*0.25 | G32: Cucumbers
C33: C1 | D33: Bacon | E33: =(E22*0.25)+(E18*0.25)
C34: C1 | D34: Pineapple | E34: =E12*0.25 | G34: Classic Carol for Tomorrow
D35: Side | E35: 1/2 Pans | G35: =Future!W24
D36: Broccoli Salad | E36: ='Production Guide'!K26
D37: Fresh Fruit | E37: ='Production Guide'!K27 | G37: C1- seasonal salad ingred, strawberries for fresh fruit & pasta salad
D38: Grape Salad | E38: ='Production Guide'!K28
D39: Pasta Salad | E39: ='Production Guide'!K29
G40: C2 & C3- sinks, sanitizer bucket, sanitize work stations, bowls & lids
C41: Broccoli salad yields (2) 1/2 pans. Pasta Salad yields (3) 1/2 pans.
G42: C4- Temperature logs
A43: Sandwich line will quick chick the flavors highlighted.

Sheet 4 Prep Cooks
B1: Date:
B3: Today's Forecast: | E3: ='Production Guide'!E2
A6: Daily Production List | G6: Item | H6: Prep
G7: Broccoli Lexis | H7: =Future!AE5
G8: Wet Grape Lexis | H8: =Future!AE6
A9: SM | B9: LG | C9: Cook | D9: Flavor | E9: #'s to Prep | G9: Dry Grape Lexis | H9: =Future!AE7
A10: ='Production Guide'!E8 | B10: ='Production Guide'!K8 | C10: C2 | D10: Classic Carol | E10: ='Production Guide'!Y8 | G10: Pasta Salad Batches | H10: =Future!AE8
A11: ='Production Guide'!E17 | B11: ='Production Guide'!K17 | C11: C2 | D11: Olivia's Old South | E11: ='Production Guide'!Y17 | G11: Grape Salad Dressing | H11: =Future!AF9
A12: ='Production Guide'!E12 | B12: ='Production Guide'!K12 | C12: C2 | D12: Fruity Fran | E12: ='Production Guide'!Y12
A13: ='Production Guide'!E19 | B13: ='Production Guide'!K19 | C13: C2 | D13: LTO | E13: ='Production Guide'!Y19 | G13: Salads | H13: Par
A14: ='Production Guide'!E10 | B14: ='Production Guide'!K10 | C14: C2 | D14: Dixie Chick | E14: ='Production Guide'!Y10 | G14: Classic Salads | H14: ='All Data'!G85
A15: ='Production Guide'!E9 | B15: ='Production Guide'!K9 | C15: C3 | D15: Cranberry Kelli | E15: ='Production Guide'!Y9 | G15: Seasonal Salads | H15: ='All Data'!G86
A16: ='Production Guide'!E11 | B16: ='Production Guide'!K11 | C16: C3 | D16: Fancy Nancy | E16: ='Production Guide'!Y11
A17: ='Production Guide'!E16 | B17: ='Production Guide'!K16 | C17: C3 | D17: Local Flavor | E17: ='Production Guide'!Y16
A18: ='Production Guide'!E15 | B18: ='Production Guide'!K15 | C18: C3 | D18: Lauryn's Lemon Basil | E18: ='Production Guide'!Y15
A19: ='Production Guide'!E21 | B19: ='Production Guide'!K21 | C19: C3 | D19: Pimento Cheese | E19: ='Production Guide'!Y21
A20: ='Production Guide'!E22 | B20: ='Production Guide'!K22 | C20: C3 | D20: Spicy Pimento Cheese | E20: ='Production Guide'!Y22 | F20: KKL
A21: ='Production Guide'!E18 | B21: ='Production Guide'!K18 | C21: C4 | D21: Sassy Scotty | E21: ='Production Guide'!Y18 | F21: =E24/3
A22: ='Production Guide'!E13 | B22: ='Production Guide'!K13 | C22: C4 | D22: Jalapeño Holly | E22: ='Production Guide'!Y13 | F22: =E24/3
A23: ='Production Guide'!E7 | B23: ='Production Guide'!K7 | C23: C4 | D23: Buffalo Barclay | E23: ='Production Guide'!Y7 | F23: =E24/3
A24: ='Production Guide'!E14 | B24: ='Production Guide'!K14 | C24: C4 | D24: Kickin Kay Lynne | E24: =MROUND('Production Guide'!Y14,3)
A25: ='Production Guide'!E6 | B25: ='Production Guide'!K6 | C25: C4 | D25: Barbie Q | E25: ='Production Guide'!Y6
A26: ='Production Guide'!E20 | B26: ='Production Guide'!K20 | C26: C4 | D26: Egg Salad | E26: ='Production Guide'!Y20
D27: Total Mixed Flavors | E27: =SUM(E10:E25)-E19-E20-E24 | G27: Salad Item Prep
G28: Salad Mix
C29: Cook | D29: Ingredient | E29: Cups to Prep | G29: Strawberries
C30: C1 | D30: Apples | E30: =(E16+E12)*0.25 | G30: Unpeeled Apples
C31: C1 | D31: Eggs | E31: =E11*0.25 | G31: Cucumbers
C32: C1 | D32: Onions | E32: =E14*0.25
C33: C1 | D33: Bacon | E33: =(E21*0.25)+(E17*0.25)
C34: C1 | D34: Pineapple | E34: =E12*0.25 | G34: Classic Carol for Tomorrow
D35: Side | E35: 1/2 Pans | G35: =Future!W24
D36: Broccoli Salad | E36: ='Production Guide'!K26 | G36: C1- seasonal salad ingred, strawberries for fresh fruit & pasta salad
D37: Fresh Fruit | E37: ='Production Guide'!K27
D38: Grape Salad | E38: ='Production Guide'!K28
D39: Pasta Salad | E39: ='Production Guide'!K29 | G39: C2 & C3- sinks, sanitizer bucket, sanitize work stations, bowls & lids
C40: Broccoli salad yields (2) 1/2 pans. Pasta Salad yields (3) 1/2 pans.
G41: C4- Temperature logs
A42: Sandwich line will quick chick the flavors highlighted.

Sheet 5 Prep Cooks 
B1: Date:
B3: Today's Forecast: | E3: ='Production Guide'!E2
A6: Daily Production List | G6: Item | H6: Prep
G7: Broccoli Lexis | H7: =Future!AE5
G8: Wet Grape Lexis | H8: =Future!AE6
A9: SM | B9: LG | C9: Cook | D9: Flavor | E9: #'s to Prep | G9: Dry Grape Lexis | H9: =Future!AE7
A10: ='Production Guide'!E8 | B10: ='Production Guide'!K8 | C10: C2 | D10: Classic Carol | E10: ='Production Guide'!Y8 | G10: Pasta Salad Batches | H10: =Future!AE8
A11: ='Production Guide'!E9 | B11: ='Production Guide'!K9 | C11: C2 | D11: Cranberry Kelli | E11: ='Production Guide'!Y9 | G11: Grape Salad Dressing | H11: =Future!AF9
A12: ='Production Guide'!E17 | B12: ='Production Guide'!K17 | C12: C2 | D12: Olivia's Old South | E12: ='Production Guide'!Y17
A13: ='Production Guide'!E20 | B13: ='Production Guide'!K20 | C13: C2 | D13: Egg Salad | E13: ='Production Guide'!Y20 | G13: Salads | H13: Par
A14: ='Production Guide'!E10 | B14: ='Production Guide'!K10 | C14: C3 | D14: Dixie Chick | E14: ='Production Guide'!Y10 | G14: Classic Salads | H14: ='All Data'!G85
A15: ='Production Guide'!E12 | B15: ='Production Guide'!K12 | C15: C3 | D15: Fruity Fran | E15: ='Production Guide'!Y12 | G15: Seasonal Salads | H15: ='All Data'!G86
A16: ='Production Guide'!E19 | B16: ='Production Guide'!K19 | C16: C3 | D16: LTO | E16: ='Production Guide'!Y19
A17: ='Production Guide'!E21 | B17: ='Production Guide'!K21 | C17: C3 | D17: Pimento Cheese | E17: ='Production Guide'!Y21
A18: ='Production Guide'!E22 | B18: ='Production Guide'!K22 | C18: C3 | D18: Spicy Pimento Cheese | E18: ='Production Guide'!Y22
A19: ='Production Guide'!E16 | B19: ='Production Guide'!K16 | C19: C4 | D19: Local Flavor | E19: ='Production Guide'!Y16
A20: ='Production Guide'!E15 | B20: ='Production Guide'!K15 | C20: C4 | D20: Lauryn's Lemon Basil | E20: ='Production Guide'!Y15
A21: ='Production Guide'!E6 | B21: ='Production Guide'!K6 | C21: C4 | D21: Barbie Q | E21: ='Production Guide'!Y6
A22: ='Production Guide'!E11 | B22: ='Production Guide'!K11 | C22: C4 | D22: Fancy Nancy | E22: ='Production Guide'!Y11 | F22: KKL
A23: ='Production Guide'!E18 | B23: ='Production Guide'!K18 | C23: C5 | D23: Sassy Scotty | E23: ='Production Guide'!Y18 | F23: =E26/3
A24: ='Production Guide'!E13 | B24: ='Production Guide'!K13 | C24: C5 | D24: Jalapeño Holly | E24: ='Production Guide'!Y13 | F24: =E26/3
A25: ='Production Guide'!E7 | B25: ='Production Guide'!K7 | C25: C5 | D25: Buffalo Barclay | E25: ='Production Guide'!Y7 | F25: =E26/3
A26: ='Production Guide'!E14 | B26: ='Production Guide'!K14 | C26: C5 | D26: Kickin Kay Lynne | E26: =MROUND('Production Guide'!Y14,3)
D27: Total Mixed Flavors | E27: =SUM(E10:E26)-E13-E17-E18-E26 | G27: Salad Item Prep
G28: Salad Mix
C29: Cook | D29: Ingredient | E29: Cups to Prep | G29: Strawberries
C30: C1 | D30: Apples | E30: =(E15+E22)*0.25 | G30: Unpeeled Apples
C31: C1 | D31: Eggs | E31: =E12*0.25 | G31: Cucumbers
C32: C1 | D32: Onions | E32: =E14*0.25
C33: C1 | D33: Bacon | E33: =(E23*0.25)+(E19*0.25)
C34: C1 | D34: Pineapples | E34: =E15*0.25 | G34: Classic Carol for Tomorrow
D35: Side | E35: 1/2 Pans | G35: =Future!W24
D36: Broccoli Salad | E36: ='Production Guide'!K26 | G36: C1- seasonal salad ingred, strawberries for fresh fruit & pasta salad
D37: Fresh Fruit | E37: ='Production Guide'!K27
D38: Grape Salad | E38: ='Production Guide'!K28
D39: Pasta Salad | E39: ='Production Guide'!K29 | G39: C2 & C3- sinks, sanitizer bucket, sanitize work stations, bowls & lids
C41: Broccoli salad yields (2) 1/2 pans. Pasta Salad yields (3) 1/2 pans. | G41: C4- Temperature logs
A43: Sandwich line will quick chick the flavors highlighted.

Sheet All Data
C2: Sales | F2: Updated by: | G2: Amanda Galbraith
C3: 142579.54 | F3: Date: | G3: 4.29.25
F4: Data Range: | G4: 3.23.25-4.26.25
P7: Directions:
A8: Quick Chicks of Chicken Salad | P8: Fill in the peach colored fields.
P9: *Make sure you enter the item sales numbers for the same total sales number that you enter in the top box.
A10: Small Bowls | F10: Flavor | G10: #'s Sold | H10: Total #'s | I10: Usage/100 | J10: Prep Amt | P10: **Example- Don't enter item sales for one day, but put the total sales of the week.
A11: Barbie Q | C11: 31 | F11: BBQ | G11: =C11 | H11: =G11/2 | I11: =G11/($C$3/100) | J11: ='Production Guide'!C6-'Production Guide'!D6 | P11: ***See CSCU if you need more direction!
A12: Buffalo Barclay | C12: 52 | F12: BB | G12: =C12 | H12: =G12/2 | I12: =G12/($C$3/100) | J12: ='Production Guide'!C7-'Production Guide'!D7
A13: Classic Carol | C13: 195 | F13: CC | G13: =C13 | H13: =G13/2 | I13: =G13/($C$3/100) | J13: ='Production Guide'!C8-'Production Guide'!D8
A14: Cranberry Kelli | C14: 106 | F14: CK | G14: =C14 | H14: =G14/2 | I14: =G14/($C$3/100) | J14: ='Production Guide'!C9-'Production Guide'!D9
A15: Dixie Chick | C15: 41 | F15: DC | G15: =C15 | H15: =G15/2 | I15: =G15/($C$3/100) | J15: ='Production Guide'!C10-'Production Guide'!D10
A16: Fancy Nancy | C16: 189 | F16: FN | G16: =C16 | H16: =G16/2 | I16: =G16/($C$3/100) | J16: ='Production Guide'!C11-'Production Guide'!D11
A17: Fruity Fran | C17: 88 | F17: FF | G17: =C17 | H17: =G17/2 | I17: =G17/($C$3/100) | J17: ='Production Guide'!C12-'Production Guide'!D12
A18: Jalapeño Holly | C18: 64 | F18: JH | G18: =C18 | H18: =G18/2 | I18: =G18/($C$3/100) | J18: ='Production Guide'!C13-'Production Guide'!D13
A19: Kickin Kay Lynne | C19: 50 | F19: KKL | G19: =C19 | H19: =G19/2 | I19: =G19/($C$3/100) | J19: ='Production Guide'!C14-'Production Guide'!D14
A20: Lauryn's Lemon Basil | C20: 54 | F20: LLB | G20: =C20 | H20: =G20/2 | I20: =G20/($C$3/100) | J20: ='Production Guide'!C15-'Production Guide'!D15
A21: Local Flavor | C21: 0 | F21: LOCAL | G21: =C21 | H21: =G21/2 | I21: =G21/($C$3/100) | J21: ='Production Guide'!C16-'Production Guide'!D16
A22: Olivia's Old South | C22: 75 | F22: OOS | G22: =C22 | H22: =G22/2 | I22: =G22/($C$3/100) | J22: ='Production Guide'!C17-'Production Guide'!D17
A23: Sassy Scotty | C23: 94 | F23: SS | G23: =C23 | H23: =G23/2 | I23: =G23/($C$3/100) | J23: ='Production Guide'!C18-'Production Guide'!D18
... A27: Spicy Pimento Cheese | C27: 26 | F27: SPICY PC | G27: =C27 | H27: =G27/2 | I27: =G27/($C$3/100) | J27: ='Production Guide'!C22-'Production Guide'!D22
A29: Large Bowls | F29: Flavor | G29: Total #'s | H29: Usage/100 | I29: Prep Amt
A30: Barbie Q | C30: 37 | F30: BBQ | G30: =C30 | H30: =G30/($C$3/100) | I30: ='Production Guide'!I6-'Production Guide'!J6
A31: Buffalo Barclay | C31: 47 | F31: BB | G31: =C31 | H31: =G31/($C$3/100) | I31: ='Production Guide'!I7-'Production Guide'!J7
A32: Classic Carol | C32: 300 | F32: CC | G32: =C32 | H32: =G32/($C$3/100) | I32: ='Production Guide'!I8-'Production Guide'!J8
A33: Cranberry Kelli | C33: 132 | F33: CK | G33: =C33 | H33: =G33/($C$3/100) | I33: ='Production Guide'!I9-'Production Guide'!J9
A34: Dixie Chick | C34: 48 | F34: DC | G34: =C34 | H34: =G34/($C$3/100) | I34: ='Production Guide'!I10-'Production Guide'!J10
A35: Fancy Nancy | C35: 290 | F35: FN | G35: =C35 | H35: =G35/($C$3/100) | I35: ='Production Guide'!I11-'Production Guide'!J11
A36: Fruity Fran | C36: 92 | F36: FF | G36: =C36 | H36: =G36/($C$3/100) | I36: ='Production Guide'!I12-'Production Guide'!J12
A37: Jalapeño Holly | C37: 82 | F37: JH | G37: =C37 | H37: =G37/($C$3/100) | I37: ='Production Guide'!I13-'Production Guide'!J13
A38: Kickin Kay Lynne | C38: 34 | F38: KKL | G38: =C38 | H38: =G38/($C$3/100) | I38: ='Production Guide'!I14-'Production Guide'!J14
A39: Lauryn's Lemon Basil | C39: 50 | F39: LLB | G39: =C39 | H39: =G39/($C$3/100) | I39: ='Production Guide'!I15-'Production Guide'!J15
A40: Local Flavor | C40: 0 | F40: LOCAL | G40: =C40 | H40: =G40/($C$3/100) | I40: ='Production Guide'!I16-'Production Guide'!J16
A41: Olivia's Old South | C41: 83 | F41: OOS | G41: =C41 | H41: =G41/($C$3/100) | I41: ='Production Guide'!I17-'Production Guide'!J17
... A46: Spicy Pimento Cheese | C46: 13 | F46: SPICY PC | G46: =C46 | H46: =G46/($C$3/100) | I46: ='Production Guide'!I22-'Production Guide'!J22
A48: Scoops + Sandwiches
A50: Scoop + Sandwich | F50: Flavor | G50: Total sc | H50: Total #'s | I50: Usage/100 | J50: Prep Amt
A51: Barbie Q | C51: 288 | F51: BBQ | G51: =C51 | H51: =G51/4 | I51: =H51/($C$3/100) | J51: ='Production Guide'!P6-'Production Guide'!Q6
A52: Buffalo Barclay | C52: 546 | F52: BB | G52: =C52 | H52: =G52/4 | I52: =H52/($C$3/100) | J52: ='Production Guide'!P7-'Production Guide'!Q7
A53: Classic Carol | C53: 1831 | F53: CC | G53: =C53 | H53: =G53/4 | I53: =H53/($C$3/100) | J53: ='Production Guide'!P8-'Production Guide'!Q8
...

Sheet Future
Q1: Day After Tomorrow's Sales Forecast
X2: ='Production Guide'!R2
A4: Small Quick Chick | G4: Large Quick Chick | M4: Line- (Any mixed flavors not in Quick Chick) | T4: Totals
A5: Flavor | C5: Par | D5: On Hand | E5: #s to Prep | G5: Flavor | I5: Par | J5: On Hand | K5: #s to Prep | M5: Flavor | O5: Par | P5: On Hand | Q5: #s to Prep | T5: Flavor | V5: Par | W5: On Hand | X5: #s to Prep | AD5: Broccoli Lexans | AE5: =(((($X$2*1.35)/100)*('All Data'!J72/2))/'All Data'!K72) | AF5: =ROUNDUP(AE5,0)
A6: Barbie Q | C6: =ROUNDUP(((($X$2*1.35)/100)*'All Data'!I11),0) | E6: =IF('All Data'!I30<0,0,'All Data'!J11) | G6: Barbie Q | I6: =ROUNDUP(((($X$2*1.35)/100)*'All Data'!H30),0) | K6: =IF('All Data'!I30<0,0,'All Data'!I30) | M6: Barbie Q | O6: =ROUNDUP(((($X$2*1.35)/100)*'All Data'!I51),0)+AA12 | Q6: =IF('All Data'!J51<0,0,'All Data'!J51) | T6: Barbie Q | V6: =(C6*0.5)+I6+O6 | W6: =(D6*0.5)+J6+P6 | X6: =IF((V6-W6)<0,0,(V6-W6)) | AD6: Wet Grapes | AE6: =(((($X$2*1.35)/100)*'All Data'!J73)/'All Data'!K73) | AF6: =ROUNDUP(AE6,0)
A7: Buffalo Barclay | C7: =ROUNDUP(((($X$2*1.35)/100)*'All Data'!I12),0) | E7: =IF('All Data'!I31<0,0,'All Data'!J12) | G7: Buffalo Barclay | I7: =ROUNDUP(((($X$2*1.35)/100)*'All Data'!H31),0) | K7: =IF('All Data'!I31<0,0,'All Data'!I31) | M7: Buffalo Barclay | O7: =ROUNDUP(((($X$2*1.35)/100)*'All Data'!I52),0)+AA13 | Q7: =IF('All Data'!J52<0,0,'All Data'!J52) | T7: Buffalo Barclay | V7: =(C7*0.5)+I7+O7 | W7: =(D7*0.5)+J7+P7 | X7: =IF((V7-W7)<0,0,(V7-W7)) | AD7: Dry Grapes | AE7: =(((($X$2*1.35)/100)*('All Data'!J74/1.75))/'All Data'!K74) | AF7: =ROUNDUP(AE7,0)
A8: Classic Carol | C8: =ROUNDUP(((($X$2*1.35)/100)*'All Data'!I13),0) | E8: =IF('All Data'!I32<0,0,'All Data'!J13) | G8: Classic Carol | I8: =ROUNDUP(((($X$2*1.35)/100)*'All Data'!H32),0) | K8: =IF('All Data'!I32<0,0,'All Data'!I32) | M8: Classic Carol | O8: =ROUNDUP(((($X$2*1.35)/100)*'All Data'!I53),0) | Q8: =IF('All Data'!J53<0,0,'All Data'!J53) | T8: Classic Carol | V8: =(C8*0.5)+I8+O8 | W8: =(D8*0.5)+J8+P8 | X8: =IF((V8-W8)<0,0,(V8-W8)) | AD8: Pasta Salad | AE8: =(((($X$2*1.35)/100)*('All Data'!J75/2.5))/'All Data'!K75) | AF8: =ROUNDUP(AE8,0)
A9: Cranberry Kelli | C9: =ROUNDUP(((($X$2*1.35)/100)*'All Data'!I14),0) | E9: =IF('All Data'!I33<0,0,'All Data'!J14) | G9: Cranberry Kelli | I9: =ROUNDUP(((($X$2*1.35)/100)*'All Data'!H33),0) | K9: =IF('All Data'!I33<0,0,'All Data'!I33) | M9: Cranberry Kelli | O9: =ROUNDUP(((($X$2*1.35)/100)*'All Data'!I54),0) | Q9: =IF('All Data'!J54<0,0,'All Data'!J54) | T9: Cranberry Kelli | V9: =(C9*0.5)+I9+O9 | W9: =(D9*0.5)+J9+P9 | X9: =IF((V9-W9)<0,0,(V9-W9)) | AD9: GS Dressing | AE9: =AE7*0.5 | AF9: =ROUNDUP(AE9,0)
A10: Dixie Chick | C10: =ROUNDUP(((($X$2*1.35)/100)*'All Data'!I15),0) | E10: =IF('All Data'!I34<0,0,'All Data'!J15) | G10: Dixie Chick | I10: =ROUNDUP(((($X$2*1.35)/100)*'All Data'!H34),0) | K10: =IF('All Data'!I34<0,0,'All Data'!I34) | M10: Dixie Chick | O10: =ROUNDUP(((($X$2*1.35)/100)*'All Data'!I55),0) | Q10: =IF('All Data'!J55<0,0,'All Data'!J55) | T10: Dixie Chick | V10: =(C10*0.5)+I10+O10 | W10: =(D10*0.5)+J10+P10 | X10: =IF((V10-W10)<0,0,(V10-W10))
A11: Fancy Nancy | C11: =ROUNDUP(((($X$2*1.35)/100)*'All Data'!I16),0) | E11: =IF('All Data'!I35<0,0,'All Data'!J16) | G11: Fancy Nancy | I11: =ROUNDUP(((($X$2*1.35)/100)*'All Data'!H35),0) | K11: =IF('All Data'!I35<0,0,'All Data'!I35) | M11: Fancy Nancy | O11: =ROUNDUP(((($X$2*1.35)/100)*'All Data'!I56),0) | Q11: =IF('All Data'!J56<0,0,'All Data'!J56) | T11: Fancy Nancy | V11: =(C11*0.5)+I11+O11 | W11: =(D11*0.5)+J11+P11 | X11: =IF((V11-W11)<0,0,(V11-W11))
A12: Fruity Fran | C12: =ROUNDUP(((($X$2*1.35)/100)*'All Data'!I17),0) | E12: =IF('All Data'!I36<0,0,'All Data'!J17) | G12: Fruity Fran | I12: =ROUNDUP(((($X$2*1.35)/100)*'All Data'!H36),0) | K12: =IF('All Data'!I36<0,0,'All Data'!I36) | M12: Fruity Fran | O12: =ROUNDUP(((($X$2*1.35)/100)*'All Data'!I57),0) | Q12: =IF('All Data'!J57<0,0,'All Data'!J57) | T12: Fruity Fran | V12: =(C12*0.5)+I12+O12 | W12: =(D12*0.5)+J12+P12 | X12: =IF((V12-W12)<0,0,(V12-W12))
A13: Jalapeño Holly | C13: =ROUNDUP(((($X$2*1.35)/100)*'All Data'!I18),0) | E13: =IF('All Data'!I37<0,0,'All Data'!J18) | G13: Jalapeño Holly | I13: =ROUNDUP(((($X$2*1.35)/100)*'All Data'!H37),0) | K13: =IF('All Data'!I37<0,0,'All Data'!I37) | M13: Jalapeño Holly | O13: =ROUNDUP(((($X$2*1.35)/100)*'All Data'!I58),0)+AA13 | Q13: =IF('All Data'!J58<0,0,'All Data'!J58) | T13: Jalapeño Holly | V13: =(C13*0.5)+I13+O13 | W13: =(D13*0.5)+J13+P13 | X13: =IF((V13-W13)<0,0,(V13-W13)) | AA13: ='Production Guide'!K48
A14: Kickin Kay Lynne | C14: =ROUNDUP(((($X$2*1.35)/100)*'All Data'!I19),0) | E14: =IF('All Data'!I38<0,0,'All Data'!J19) | G14: Kickin Kay Lynne | I14: =ROUNDUP(((($X$2*1.35)/100)*'All Data'!H38),0) | K14: =IF('All Data'!I38<0,0,'All Data'!I38) | M14: Kickin Kay Lynne | O14: =ROUNDUP(((($X$2*1.35)/100)*'All Data'!I59),0) | Q14: =IF('All Data'!J59<0,0,'All Data'!J59) | T14: Kickin Kay Lynne | V14: =(C14*0.5)+I14+O14 | W14: =(D14*0.5)+J14+P14 | X14: =IF((V14-W14)<0,0,(V14-W14))
A15: Lauryn's L. Basil | C15: =ROUNDUP(((($X$2*1.35)/100)*'All Data'!I20),0) | E15: =IF('All Data'!I39<0,0,'All Data'!J20) | G15: Lauryn's L. Basil | I15: =ROUNDUP(((($X$2*1.35)/100)*'All Data'!H39),0) | K15: =IF('All Data'!I39<0,0,'All Data'!I39) | M15: Lauryn's L. Basil | O15: =ROUNDUP(((($X$2*1.35)/100)*'All Data'!I60),0) | Q15: =IF('All Data'!J60<0,0,'All Data'!J60) | T15: Lauryn's L. Basil | V15: =(C15*0.5)+I15+O15 | W15: =(D15*0.5)+J15+P15 | X15: =IF((V15-W15)<0,0,(V15-W15))
A16: Local Flavor | C16: =ROUNDUP(((($X$2*1.35)/100)*'All Data'!I21),0) | E16: =IF('All Data'!I40<0,0,'All Data'!J21) | G16: Local Flavor | I16: =ROUNDUP(((($X$2*1.35)/100)*'All Data'!H40),0) | K16: =IF('All Data'!I40<0,0,'All Data'!I40) | M16: Local Flavor | O16: =ROUNDUP(((($X$2*1.35)/100)*'All Data'!I61),0) | Q16: =IF('All Data'!J61<0,0,'All Data'!J61) | T16: Local Flavor | V16: =(C16*0.5)+I16+O16 | W16: =(D16*0.5)+J16+P16 | X16: =IF((V16-W16)<0,0,(V16-W16))
A17: Olivia's Old South | C17: =ROUNDUP(((($X$2*1.35)/100)*'All Data'!I22),0) | E17: =IF('All Data'!I41<0,0,'All Data'!J22) | G17: Olivia's Old South | I17: =ROUNDUP(((($X$2*1.35)/100)*'All Data'!H41),0) | K17: =IF('All Data'!I41<0,0,'All Data'!I41) | M17: Olivia's Old South | O17: =ROUNDUP(((($X$2*1.35)/100)*'All Data'!I62),0) | Q17: =IF('All Data'!J62<0,0,'All Data'!J62) | T17: Olivia's Old South | V17: =(C17*0.5)+I17+O17 | W17: =(D17*0.5)+J17+P17 | X17: =IF((V17-W17)<0,0,(V17-W17))
A18: Sassy Scotty | C18: =ROUNDUP(((($X$2*1.35)/100)*'All Data'!I23),0) | E18: =IF('All Data'!I42<0,0,'All Data'!J23) | G18: Sassy Scotty | I18: =ROUNDUP(((($X$2*1.35)/100)*'All Data'!H42),0) | K18: =IF('All Data'!I42<0,0,'All Data'!I42) | M18: Sassy Scotty | O18: =ROUNDUP(((($X$2*1.35)/100)*'All Data'!I63),0)+AA13 | Q18: =IF('All Data'!J63<0,0,'All Data'!J63) | T18: Sassy Scotty | V18: =(C18*0.5)+I18+O18 | W18: =(D18*0.5)+J18+P18 | X18: =IF((V18-W18)<0,0,(V18-W18))
A19: LTO | C19: =ROUNDUP(((($X$2*1.35)/100)*'All Data'!I24),0) | E19: =IF('All Data'!I43<0,0,'All Data'!J24) | G19: LTO | I19: =ROUNDUP(((($X$2*1.35)/100)*'All Data'!H43),0) | K19: =IF('All Data'!I43<0,0,'All Data'!I43) | M19: LTO | O19: =ROUNDUP(((($X$2*1.35)/100)*'All Data'!I64),0) | Q19: =IF('All Data'!J64<0,0,'All Data'!J64) | T19: LTO | V19: =(C19*0.5)+I19+O19 | W19: =(D19*0.5)+J19+P19 | X19: =IF((V19-W19)<0,0,(V19-W19))
A20: Egg Salad | C20: =ROUNDUP(((($X$2*1.35)/100)*'All Data'!I25),0) | E20: =IF('All Data'!I44<0,0,'All Data'!J25) | G20: Egg Salad | I20: =ROUNDUP(((($X$2*1.35)/100)*'All Data'!H44),0) | K20: =IF('All Data'!I44<0,0,'All Data'!I44) | M20: Egg Salad | O20: =ROUNDUP(((($X$2*1.35)/100)*'All Data'!I65),0) | Q20: =IF('All Data'!J65<0,0,'All Data'!J65) | T20: Egg Salad | V20: =(C20*0.5)+I20+O20 | W20: =(D20*0.5)+J20+P20 | X20: =IF((V20-W20)<0,0,(V20-W20))
A21: Pimento Cheese | C21: =ROUNDUP(((($X$2*1.35)/100)*'All Data'!I26),0) | E21: =IF('All Data'!I45<0,0,'All Data'!J26) | G21: Pimento Cheese | I21: =ROUNDUP(((($X$2*1.35)/100)*'All Data'!H45),0) | K21: =IF('All Data'!I45<0,0,'All Data'!I45) | M21: Pimento Cheese | O21: =ROUNDUP(((($X$2*1.35)/100)*'All Data'!I66),0) | Q21: =IF('All Data'!J66<0,0,'All Data'!J66) | T21: Pimento Cheese | V21: =(C21*0.5)+I21+O21 | W21: =(D21*0.5)+J21+P21 | X21: =IF((V21-W21)<0,0,(V21-W21))
A22: Spicy P. Cheese | C22: =ROUNDUP(((($X$2*1.35)/100)*'All Data'!I27),0) | E22: =IF('All Data'!I46<0,0,'All Data'!J27) | G22: Spicy P. Cheese | I22: =ROUNDUP(((($X$2*1.35)/100)*'All Data'!H46),0) | K22: =IF('All Data'!I46<0,0,'All Data'!I46) | M22: Spicy P. Cheese | O22: =ROUNDUP(((($X$2*1.35)/100)*'All Data'!I67),0) | Q22: =IF('All Data'!J67<0,0,'All Data'!J67) | T22: Spicy P. Cheese | V22: =(C22*0.5)+I22+O22 | W22: =(D22*0.5)+J22+P22 | X22: =IF((V22-W22)<0,0,(V22-W22))
T24: Total Classic Carol | W24: =SUM(X6:Y19)-X14
G25: Sides | I25: Daily Par (in 1/2 pans)
G26: Broccoli Salad | I26: =((($X$2*1.35)/100)*'All Data'!J72)/'All Data'!K72
G27: Fresh Fruit | I27: =((($X$2*1.35)/100)*'All Data'!J73)/'All Data'!K73
G28: Grape Salad | I28: =((($X$2*1.35)/100)*'All Data'!J74)/'All Data'!K74
G29: Pasta Salad | I29: =((($X$2*1.35)/100)*'All Data'!J75)/'All Data'!K75
G32: Proj. Sales | H32: Cut Broccoli Lexis | I32: Dry | J32: Wet | K32: Batches of GrapeSaladDressing | L32: Pimento Cheese Batches | M32: Pasta
I33: Grape | J33: Grape* | M33: Salad Batches
I34: Lexis | J34: Lexis
G35: 2000 | H35: 2 | I35: 1 | J35: .75 | K35: 1 | L35: 1 | M35: 1
G36: 3000 | H36: 2 | I36: 2 | J36: 1 | K36: 1 | L36: 1 | M36: 1
G37: 4000 | H37: 3 | I37: 2 | J37: 1.5 | K37: 1 | L37: 2 | M37: 1
G38: 5000 | H38: 4 | I38: 3 | J38: 1.5 | K38: 2 | L38: 2 | M38: 1
G39: 6000 | H39: 4 | I39: 3 | J39: 2 | K39: 2 | L39: 2 | M39: 1
G40: 7000 | H40: 5 | I40: 4 | J40: 2 | K40: 2 | L40: 2 | M40: 2
G41: 8000 | H41: 6 | I41: 5 | J41: 2.5 | K41: 3 | L41: 3 | M41: 2
G42: 9000 | H42: 6 | I42: 5 | J42: 3 | K42: 3 | L42: 3 | M42: 2
G43: 10,000 | H43: 7 | I43: 6 | J43: 3 | K43: 3 | L43: 3 | M43: 2
G44: 11,000 | H44: 8 | I44: 6 | J44: 3.5 | K44: 3 | L44: 3 | M44: 2
